[2025-10-17T08:09:07.033+0000] {taskinstance.py:1159} INFO - Dependencies all met for dep_context=non-requeueable deps ti=<TaskInstance: csv_etl_pipeline.soda_scan_2 scheduled__2025-10-16T20:00:00+00:00 [queued]>
[2025-10-17T08:09:07.043+0000] {taskinstance.py:1159} INFO - Dependencies all met for dep_context=requeueable deps ti=<TaskInstance: csv_etl_pipeline.soda_scan_2 scheduled__2025-10-16T20:00:00+00:00 [queued]>
[2025-10-17T08:09:07.044+0000] {taskinstance.py:1361} INFO - Starting attempt 1 of 1
[2025-10-17T08:09:07.056+0000] {taskinstance.py:1382} INFO - Executing <Task(BashOperator): soda_scan_2> on 2025-10-16 20:00:00+00:00
[2025-10-17T08:09:07.063+0000] {standard_task_runner.py:57} INFO - Started process 97 to run task
[2025-10-17T08:09:07.068+0000] {standard_task_runner.py:84} INFO - Running: ['***', 'tasks', 'run', 'csv_etl_pipeline', 'soda_scan_2', 'scheduled__2025-10-16T20:00:00+00:00', '--job-id', '8', '--raw', '--subdir', 'DAGS_FOLDER/etl.py', '--cfg-path', '/tmp/tmp8udievqq']
[2025-10-17T08:09:07.069+0000] {standard_task_runner.py:85} INFO - Job 8: Subtask soda_scan_2
[2025-10-17T08:09:07.118+0000] {task_command.py:416} INFO - Running <TaskInstance: csv_etl_pipeline.soda_scan_2 scheduled__2025-10-16T20:00:00+00:00 [running]> on host b7bfdf78a159
[2025-10-17T08:09:07.186+0000] {taskinstance.py:1662} INFO - Exporting env vars: AIRFLOW_CTX_DAG_OWNER='***' AIRFLOW_CTX_DAG_ID='csv_etl_pipeline' AIRFLOW_CTX_TASK_ID='soda_scan_2' AIRFLOW_CTX_EXECUTION_DATE='2025-10-16T20:00:00+00:00' AIRFLOW_CTX_TRY_NUMBER='1' AIRFLOW_CTX_DAG_RUN_ID='scheduled__2025-10-16T20:00:00+00:00'
[2025-10-17T08:09:07.190+0000] {subprocess.py:63} INFO - Tmp dir root location: /tmp
[2025-10-17T08:09:07.191+0000] {subprocess.py:75} INFO - Running command: ['/bin/bash', '-c', 'soda scan -d ***_pg -c /opt/***/dags/soda/configuration.yml /opt/***/dags/soda/checks_2.yml']
[2025-10-17T08:09:07.204+0000] {subprocess.py:86} INFO - Output:
[2025-10-17T08:09:08.097+0000] {subprocess.py:93} INFO - [08:09:08] Soda Core 3.5.6
[2025-10-17T08:09:08.158+0000] {subprocess.py:93} INFO - [08:09:08] Counting invalid without valid or invalid specification does not make sense. ("invalid_count(price) = 0" @ line=9,col=5 in /opt/***/dags/soda/checks_2.yml)
[2025-10-17T08:09:08.160+0000] {subprocess.py:93} INFO - [08:09:08] Scan summary:
[2025-10-17T08:09:08.160+0000] {subprocess.py:93} INFO - [08:09:08] 6/6 checks PASSED:
[2025-10-17T08:09:08.160+0000] {subprocess.py:93} INFO - [08:09:08]     games in ***_pg
[2025-10-17T08:09:08.160+0000] {subprocess.py:93} INFO - [08:09:08]       row_count > 0 [PASSED]
[2025-10-17T08:09:08.161+0000] {subprocess.py:93} INFO - [08:09:08]       missing_count(game) = 0 [PASSED]
[2025-10-17T08:09:08.161+0000] {subprocess.py:93} INFO - [08:09:08]       duplicate_count(urlgame) = 0 [PASSED]
[2025-10-17T08:09:08.161+0000] {subprocess.py:93} INFO - [08:09:08]     prices in ***_pg
[2025-10-17T08:09:08.161+0000] {subprocess.py:93} INFO - [08:09:08]       row_count > 0 [PASSED]
[2025-10-17T08:09:08.161+0000] {subprocess.py:93} INFO - [08:09:08]       missing_count(price) = 0 [PASSED]
[2025-10-17T08:09:08.161+0000] {subprocess.py:93} INFO - [08:09:08]       invalid_count(price) = 0 [PASSED]
[2025-10-17T08:09:08.161+0000] {subprocess.py:93} INFO - [08:09:08] All is good. No failures. No warnings. No errors.
[2025-10-17T08:09:08.367+0000] {subprocess.py:97} INFO - Command exited with return code 0
[2025-10-17T08:09:08.390+0000] {taskinstance.py:1400} INFO - Marking task as SUCCESS. dag_id=csv_etl_pipeline, task_id=soda_scan_2, execution_date=20251016T200000, start_date=20251017T080907, end_date=20251017T080908
[2025-10-17T08:09:08.444+0000] {local_task_job_runner.py:228} INFO - Task exited with return code 0
[2025-10-17T08:09:08.458+0000] {taskinstance.py:2778} INFO - 0 downstream tasks scheduled from follow-on schedule check
[2025-10-17T08:12:50.812+0000] {taskinstance.py:1159} INFO - Dependencies all met for dep_context=non-requeueable deps ti=<TaskInstance: csv_etl_pipeline.soda_scan_2 scheduled__2025-10-16T20:00:00+00:00 [queued]>
[2025-10-17T08:12:50.819+0000] {taskinstance.py:1159} INFO - Dependencies all met for dep_context=requeueable deps ti=<TaskInstance: csv_etl_pipeline.soda_scan_2 scheduled__2025-10-16T20:00:00+00:00 [queued]>
[2025-10-17T08:12:50.819+0000] {taskinstance.py:1361} INFO - Starting attempt 1 of 1
[2025-10-17T08:12:50.828+0000] {taskinstance.py:1382} INFO - Executing <Task(BashOperator): soda_scan_2> on 2025-10-16 20:00:00+00:00
[2025-10-17T08:12:50.834+0000] {standard_task_runner.py:57} INFO - Started process 105 to run task
[2025-10-17T08:12:50.838+0000] {standard_task_runner.py:84} INFO - Running: ['***', 'tasks', 'run', 'csv_etl_pipeline', 'soda_scan_2', 'scheduled__2025-10-16T20:00:00+00:00', '--job-id', '8', '--raw', '--subdir', 'DAGS_FOLDER/etl.py', '--cfg-path', '/tmp/tmp12k24b66']
[2025-10-17T08:12:50.839+0000] {standard_task_runner.py:85} INFO - Job 8: Subtask soda_scan_2
[2025-10-17T08:12:50.886+0000] {task_command.py:416} INFO - Running <TaskInstance: csv_etl_pipeline.soda_scan_2 scheduled__2025-10-16T20:00:00+00:00 [running]> on host 532d771fe9a3
[2025-10-17T08:12:50.950+0000] {taskinstance.py:1662} INFO - Exporting env vars: AIRFLOW_CTX_DAG_OWNER='***' AIRFLOW_CTX_DAG_ID='csv_etl_pipeline' AIRFLOW_CTX_TASK_ID='soda_scan_2' AIRFLOW_CTX_EXECUTION_DATE='2025-10-16T20:00:00+00:00' AIRFLOW_CTX_TRY_NUMBER='1' AIRFLOW_CTX_DAG_RUN_ID='scheduled__2025-10-16T20:00:00+00:00'
[2025-10-17T08:12:50.953+0000] {subprocess.py:63} INFO - Tmp dir root location: /tmp
[2025-10-17T08:12:50.954+0000] {subprocess.py:75} INFO - Running command: ['/bin/bash', '-c', 'soda scan -d ***_pg -c /opt/***/dags/soda/configuration.yml /opt/***/dags/soda/checks_2.yml']
[2025-10-17T08:12:50.965+0000] {subprocess.py:86} INFO - Output:
[2025-10-17T08:12:52.039+0000] {subprocess.py:93} INFO - [08:12:52] Soda Core 3.5.6
[2025-10-17T08:12:52.158+0000] {subprocess.py:93} INFO - [08:12:52] Counting invalid without valid or invalid specification does not make sense. ("invalid_count(price) = 0" @ line=9,col=5 in /opt/***/dags/soda/checks_2.yml)
[2025-10-17T08:12:52.161+0000] {subprocess.py:93} INFO - [08:12:52] Scan summary:
[2025-10-17T08:12:52.161+0000] {subprocess.py:93} INFO - [08:12:52] 6/6 checks PASSED:
[2025-10-17T08:12:52.161+0000] {subprocess.py:93} INFO - [08:12:52]     games in ***_pg
[2025-10-17T08:12:52.161+0000] {subprocess.py:93} INFO - [08:12:52]       row_count > 0 [PASSED]
[2025-10-17T08:12:52.161+0000] {subprocess.py:93} INFO - [08:12:52]       missing_count(game) = 0 [PASSED]
[2025-10-17T08:12:52.161+0000] {subprocess.py:93} INFO - [08:12:52]       duplicate_count(urlgame) = 0 [PASSED]
[2025-10-17T08:12:52.161+0000] {subprocess.py:93} INFO - [08:12:52]     prices in ***_pg
[2025-10-17T08:12:52.161+0000] {subprocess.py:93} INFO - [08:12:52]       row_count > 0 [PASSED]
[2025-10-17T08:12:52.162+0000] {subprocess.py:93} INFO - [08:12:52]       missing_count(price) = 0 [PASSED]
[2025-10-17T08:12:52.162+0000] {subprocess.py:93} INFO - [08:12:52]       invalid_count(price) = 0 [PASSED]
[2025-10-17T08:12:52.162+0000] {subprocess.py:93} INFO - [08:12:52] All is good. No failures. No warnings. No errors.
[2025-10-17T08:12:52.540+0000] {subprocess.py:97} INFO - Command exited with return code 0
[2025-10-17T08:12:52.572+0000] {taskinstance.py:1400} INFO - Marking task as SUCCESS. dag_id=csv_etl_pipeline, task_id=soda_scan_2, execution_date=20251016T200000, start_date=20251017T081250, end_date=20251017T081252
[2025-10-17T08:12:52.616+0000] {local_task_job_runner.py:228} INFO - Task exited with return code 0
[2025-10-17T08:12:52.638+0000] {taskinstance.py:2778} INFO - 0 downstream tasks scheduled from follow-on schedule check
[2025-10-17T08:15:02.939+0000] {taskinstance.py:1159} INFO - Dependencies all met for dep_context=non-requeueable deps ti=<TaskInstance: csv_etl_pipeline.soda_scan_2 scheduled__2025-10-16T20:00:00+00:00 [queued]>
[2025-10-17T08:15:02.951+0000] {taskinstance.py:1159} INFO - Dependencies all met for dep_context=requeueable deps ti=<TaskInstance: csv_etl_pipeline.soda_scan_2 scheduled__2025-10-16T20:00:00+00:00 [queued]>
[2025-10-17T08:15:02.952+0000] {taskinstance.py:1361} INFO - Starting attempt 1 of 1
[2025-10-17T08:15:02.965+0000] {taskinstance.py:1382} INFO - Executing <Task(BashOperator): soda_scan_2> on 2025-10-16 20:00:00+00:00
[2025-10-17T08:15:02.971+0000] {standard_task_runner.py:57} INFO - Started process 104 to run task
[2025-10-17T08:15:02.978+0000] {standard_task_runner.py:84} INFO - Running: ['***', 'tasks', 'run', 'csv_etl_pipeline', 'soda_scan_2', 'scheduled__2025-10-16T20:00:00+00:00', '--job-id', '8', '--raw', '--subdir', 'DAGS_FOLDER/etl.py', '--cfg-path', '/tmp/tmp2q9haxtx']
[2025-10-17T08:15:02.983+0000] {standard_task_runner.py:85} INFO - Job 8: Subtask soda_scan_2
[2025-10-17T08:15:03.044+0000] {task_command.py:416} INFO - Running <TaskInstance: csv_etl_pipeline.soda_scan_2 scheduled__2025-10-16T20:00:00+00:00 [running]> on host e82aa66f271e
[2025-10-17T08:15:03.130+0000] {taskinstance.py:1662} INFO - Exporting env vars: AIRFLOW_CTX_DAG_OWNER='***' AIRFLOW_CTX_DAG_ID='csv_etl_pipeline' AIRFLOW_CTX_TASK_ID='soda_scan_2' AIRFLOW_CTX_EXECUTION_DATE='2025-10-16T20:00:00+00:00' AIRFLOW_CTX_TRY_NUMBER='1' AIRFLOW_CTX_DAG_RUN_ID='scheduled__2025-10-16T20:00:00+00:00'
[2025-10-17T08:15:03.133+0000] {subprocess.py:63} INFO - Tmp dir root location: /tmp
[2025-10-17T08:15:03.134+0000] {subprocess.py:75} INFO - Running command: ['/bin/bash', '-c', 'soda scan -d ***_pg -c /opt/***/dags/soda/configuration.yml /opt/***/dags/soda/checks_2.yml']
[2025-10-17T08:15:03.148+0000] {subprocess.py:86} INFO - Output:
[2025-10-17T08:15:04.166+0000] {subprocess.py:93} INFO - [08:15:04] Soda Core 3.5.6
[2025-10-17T08:15:04.239+0000] {subprocess.py:93} INFO - [08:15:04] Counting invalid without valid or invalid specification does not make sense. ("invalid_count(price) = 0" @ line=9,col=5 in /opt/***/dags/soda/checks_2.yml)
[2025-10-17T08:15:04.242+0000] {subprocess.py:93} INFO - [08:15:04] Scan summary:
[2025-10-17T08:15:04.242+0000] {subprocess.py:93} INFO - [08:15:04] 6/6 checks PASSED:
[2025-10-17T08:15:04.242+0000] {subprocess.py:93} INFO - [08:15:04]     games in ***_pg
[2025-10-17T08:15:04.242+0000] {subprocess.py:93} INFO - [08:15:04]       row_count > 0 [PASSED]
[2025-10-17T08:15:04.243+0000] {subprocess.py:93} INFO - [08:15:04]       missing_count(game) = 0 [PASSED]
[2025-10-17T08:15:04.243+0000] {subprocess.py:93} INFO - [08:15:04]       duplicate_count(urlgame) = 0 [PASSED]
[2025-10-17T08:15:04.243+0000] {subprocess.py:93} INFO - [08:15:04]     prices in ***_pg
[2025-10-17T08:15:04.243+0000] {subprocess.py:93} INFO - [08:15:04]       row_count > 0 [PASSED]
[2025-10-17T08:15:04.243+0000] {subprocess.py:93} INFO - [08:15:04]       missing_count(price) = 0 [PASSED]
[2025-10-17T08:15:04.243+0000] {subprocess.py:93} INFO - [08:15:04]       invalid_count(price) = 0 [PASSED]
[2025-10-17T08:15:04.243+0000] {subprocess.py:93} INFO - [08:15:04] All is good. No failures. No warnings. No errors.
[2025-10-17T08:15:04.447+0000] {subprocess.py:97} INFO - Command exited with return code 0
[2025-10-17T08:15:04.469+0000] {taskinstance.py:1400} INFO - Marking task as SUCCESS. dag_id=csv_etl_pipeline, task_id=soda_scan_2, execution_date=20251016T200000, start_date=20251017T081502, end_date=20251017T081504
[2025-10-17T08:15:04.515+0000] {local_task_job_runner.py:228} INFO - Task exited with return code 0
[2025-10-17T08:15:04.530+0000] {taskinstance.py:2778} INFO - 0 downstream tasks scheduled from follow-on schedule check
[2025-10-17T08:28:27.120+0000] {taskinstance.py:1159} INFO - Dependencies all met for dep_context=non-requeueable deps ti=<TaskInstance: csv_etl_pipeline.soda_scan_2 scheduled__2025-10-16T20:00:00+00:00 [queued]>
[2025-10-17T08:28:27.127+0000] {taskinstance.py:1159} INFO - Dependencies all met for dep_context=requeueable deps ti=<TaskInstance: csv_etl_pipeline.soda_scan_2 scheduled__2025-10-16T20:00:00+00:00 [queued]>
[2025-10-17T08:28:27.128+0000] {taskinstance.py:1361} INFO - Starting attempt 1 of 1
[2025-10-17T08:28:27.136+0000] {taskinstance.py:1382} INFO - Executing <Task(BashOperator): soda_scan_2> on 2025-10-16 20:00:00+00:00
[2025-10-17T08:28:27.141+0000] {standard_task_runner.py:57} INFO - Started process 97 to run task
[2025-10-17T08:28:27.145+0000] {standard_task_runner.py:84} INFO - Running: ['***', 'tasks', 'run', 'csv_etl_pipeline', 'soda_scan_2', 'scheduled__2025-10-16T20:00:00+00:00', '--job-id', '8', '--raw', '--subdir', 'DAGS_FOLDER/etl.py', '--cfg-path', '/tmp/tmpsg0d_fao']
[2025-10-17T08:28:27.149+0000] {standard_task_runner.py:85} INFO - Job 8: Subtask soda_scan_2
[2025-10-17T08:28:27.194+0000] {task_command.py:416} INFO - Running <TaskInstance: csv_etl_pipeline.soda_scan_2 scheduled__2025-10-16T20:00:00+00:00 [running]> on host 0912e2f8d1fc
[2025-10-17T08:28:27.254+0000] {taskinstance.py:1662} INFO - Exporting env vars: AIRFLOW_CTX_DAG_OWNER='***' AIRFLOW_CTX_DAG_ID='csv_etl_pipeline' AIRFLOW_CTX_TASK_ID='soda_scan_2' AIRFLOW_CTX_EXECUTION_DATE='2025-10-16T20:00:00+00:00' AIRFLOW_CTX_TRY_NUMBER='1' AIRFLOW_CTX_DAG_RUN_ID='scheduled__2025-10-16T20:00:00+00:00'
[2025-10-17T08:28:27.255+0000] {subprocess.py:63} INFO - Tmp dir root location: /tmp
[2025-10-17T08:28:27.256+0000] {subprocess.py:75} INFO - Running command: ['/bin/bash', '-c', 'soda scan -d ***_pg -c /opt/***/dags/soda/configuration.yml /opt/***/dags/soda/checks_2.yml']
[2025-10-17T08:28:27.267+0000] {subprocess.py:86} INFO - Output:
[2025-10-17T08:28:28.075+0000] {subprocess.py:93} INFO - [08:28:28] Soda Core 3.5.6
[2025-10-17T08:28:28.127+0000] {subprocess.py:93} INFO - [08:28:28] Could not add SodaCL file /opt/***/dags/soda/checks_2.yml
[2025-10-17T08:28:28.127+0000] {subprocess.py:93} INFO -   | 'NoneType' object is not iterable
[2025-10-17T08:28:28.142+0000] {subprocess.py:93} INFO - [08:28:28] Counting invalid without valid or invalid specification does not make sense. ("invalid_count(price) = 0" @ line=9,col=5 in /opt/***/dags/soda/checks_2.yml)
[2025-10-17T08:28:28.144+0000] {subprocess.py:93} INFO - [08:28:28] Scan summary:
[2025-10-17T08:28:28.145+0000] {subprocess.py:93} INFO - [08:28:28] 6/6 checks PASSED:
[2025-10-17T08:28:28.145+0000] {subprocess.py:93} INFO - [08:28:28]     games in ***_pg
[2025-10-17T08:28:28.145+0000] {subprocess.py:93} INFO - [08:28:28]       row_count > 0 [PASSED]
[2025-10-17T08:28:28.145+0000] {subprocess.py:93} INFO - [08:28:28]       missing_count(game) = 0 [PASSED]
[2025-10-17T08:28:28.145+0000] {subprocess.py:93} INFO - [08:28:28]       duplicate_count(urlgame) = 0 [PASSED]
[2025-10-17T08:28:28.145+0000] {subprocess.py:93} INFO - [08:28:28]     prices in ***_pg
[2025-10-17T08:28:28.145+0000] {subprocess.py:93} INFO - [08:28:28]       row_count > 0 [PASSED]
[2025-10-17T08:28:28.145+0000] {subprocess.py:93} INFO - [08:28:28]       missing_count(price) = 0 [PASSED]
[2025-10-17T08:28:28.145+0000] {subprocess.py:93} INFO - [08:28:28]       invalid_count(price) = 0 [PASSED]
[2025-10-17T08:28:28.145+0000] {subprocess.py:93} INFO - [08:28:28] 1 errors.
[2025-10-17T08:28:28.145+0000] {subprocess.py:93} INFO - [08:28:28] Oops! 1 error. 0 failures. 0 warnings. 6 pass.
[2025-10-17T08:28:28.145+0000] {subprocess.py:93} INFO - ERRORS:
[2025-10-17T08:28:28.146+0000] {subprocess.py:93} INFO - [08:28:28] Could not add SodaCL file /opt/***/dags/soda/checks_2.yml
[2025-10-17T08:28:28.146+0000] {subprocess.py:93} INFO -   | 'NoneType' object is not iterable
[2025-10-17T08:28:28.338+0000] {subprocess.py:97} INFO - Command exited with return code 3
[2025-10-17T08:28:28.348+0000] {taskinstance.py:1937} ERROR - Task failed with exception
Traceback (most recent call last):
  File "/home/airflow/.local/lib/python3.8/site-packages/airflow/operators/bash.py", line 210, in execute
    raise AirflowException(
airflow.exceptions.AirflowException: Bash command failed. The command returned a non-zero exit code 3.
[2025-10-17T08:28:28.351+0000] {taskinstance.py:1400} INFO - Marking task as FAILED. dag_id=csv_etl_pipeline, task_id=soda_scan_2, execution_date=20251016T200000, start_date=20251017T082827, end_date=20251017T082828
[2025-10-17T08:28:28.361+0000] {standard_task_runner.py:104} ERROR - Failed to execute job 8 for task soda_scan_2 (Bash command failed. The command returned a non-zero exit code 3.; 97)
[2025-10-17T08:28:28.400+0000] {local_task_job_runner.py:228} INFO - Task exited with return code 1
[2025-10-17T08:28:28.413+0000] {taskinstance.py:2778} INFO - 0 downstream tasks scheduled from follow-on schedule check
[2025-10-17T08:41:58.073+0000] {taskinstance.py:1159} INFO - Dependencies all met for dep_context=non-requeueable deps ti=<TaskInstance: csv_etl_pipeline.soda_scan_2 scheduled__2025-10-16T20:00:00+00:00 [queued]>
[2025-10-17T08:41:58.080+0000] {taskinstance.py:1159} INFO - Dependencies all met for dep_context=requeueable deps ti=<TaskInstance: csv_etl_pipeline.soda_scan_2 scheduled__2025-10-16T20:00:00+00:00 [queued]>
[2025-10-17T08:41:58.080+0000] {taskinstance.py:1361} INFO - Starting attempt 1 of 1
[2025-10-17T08:41:58.091+0000] {taskinstance.py:1382} INFO - Executing <Task(BashOperator): soda_scan_2> on 2025-10-16 20:00:00+00:00
[2025-10-17T08:41:58.097+0000] {standard_task_runner.py:57} INFO - Started process 105 to run task
[2025-10-17T08:41:58.100+0000] {standard_task_runner.py:84} INFO - Running: ['***', 'tasks', 'run', 'csv_etl_pipeline', 'soda_scan_2', 'scheduled__2025-10-16T20:00:00+00:00', '--job-id', '8', '--raw', '--subdir', 'DAGS_FOLDER/etl.py', '--cfg-path', '/tmp/tmpaxpahd7f']
[2025-10-17T08:41:58.103+0000] {standard_task_runner.py:85} INFO - Job 8: Subtask soda_scan_2
[2025-10-17T08:41:58.143+0000] {task_command.py:416} INFO - Running <TaskInstance: csv_etl_pipeline.soda_scan_2 scheduled__2025-10-16T20:00:00+00:00 [running]> on host c22c7f7cd908
[2025-10-17T08:41:58.199+0000] {taskinstance.py:1662} INFO - Exporting env vars: AIRFLOW_CTX_DAG_OWNER='***' AIRFLOW_CTX_DAG_ID='csv_etl_pipeline' AIRFLOW_CTX_TASK_ID='soda_scan_2' AIRFLOW_CTX_EXECUTION_DATE='2025-10-16T20:00:00+00:00' AIRFLOW_CTX_TRY_NUMBER='1' AIRFLOW_CTX_DAG_RUN_ID='scheduled__2025-10-16T20:00:00+00:00'
[2025-10-17T08:41:58.202+0000] {subprocess.py:63} INFO - Tmp dir root location: /tmp
[2025-10-17T08:41:58.203+0000] {subprocess.py:75} INFO - Running command: ['/bin/bash', '-c', 'soda scan -d ***_pg -c /opt/***/dags/soda/configuration.yml /opt/***/dags/soda/checks_2.yml']
[2025-10-17T08:41:58.214+0000] {subprocess.py:86} INFO - Output:
[2025-10-17T08:41:59.040+0000] {subprocess.py:93} INFO - [08:41:59] Soda Core 3.5.6
[2025-10-17T08:41:59.094+0000] {subprocess.py:93} INFO - [08:41:59] Could not add SodaCL file /opt/***/dags/soda/checks_2.yml
[2025-10-17T08:41:59.094+0000] {subprocess.py:93} INFO -   | 'NoneType' object is not iterable
[2025-10-17T08:41:59.108+0000] {subprocess.py:93} INFO - [08:41:59] Counting invalid without valid or invalid specification does not make sense. ("invalid_count(price) = 0" @ line=9,col=5 in /opt/***/dags/soda/checks_2.yml)
[2025-10-17T08:41:59.110+0000] {subprocess.py:93} INFO - [08:41:59] Scan summary:
[2025-10-17T08:41:59.110+0000] {subprocess.py:93} INFO - [08:41:59] 6/6 checks PASSED:
[2025-10-17T08:41:59.111+0000] {subprocess.py:93} INFO - [08:41:59]     games in ***_pg
[2025-10-17T08:41:59.111+0000] {subprocess.py:93} INFO - [08:41:59]       row_count > 0 [PASSED]
[2025-10-17T08:41:59.111+0000] {subprocess.py:93} INFO - [08:41:59]       missing_count(game) = 0 [PASSED]
[2025-10-17T08:41:59.111+0000] {subprocess.py:93} INFO - [08:41:59]       duplicate_count(urlgame) = 0 [PASSED]
[2025-10-17T08:41:59.111+0000] {subprocess.py:93} INFO - [08:41:59]     prices in ***_pg
[2025-10-17T08:41:59.111+0000] {subprocess.py:93} INFO - [08:41:59]       row_count > 0 [PASSED]
[2025-10-17T08:41:59.111+0000] {subprocess.py:93} INFO - [08:41:59]       missing_count(price) = 0 [PASSED]
[2025-10-17T08:41:59.111+0000] {subprocess.py:93} INFO - [08:41:59]       invalid_count(price) = 0 [PASSED]
[2025-10-17T08:41:59.111+0000] {subprocess.py:93} INFO - [08:41:59] 1 errors.
[2025-10-17T08:41:59.111+0000] {subprocess.py:93} INFO - [08:41:59] Oops! 1 error. 0 failures. 0 warnings. 6 pass.
[2025-10-17T08:41:59.111+0000] {subprocess.py:93} INFO - ERRORS:
[2025-10-17T08:41:59.111+0000] {subprocess.py:93} INFO - [08:41:59] Could not add SodaCL file /opt/***/dags/soda/checks_2.yml
[2025-10-17T08:41:59.111+0000] {subprocess.py:93} INFO -   | 'NoneType' object is not iterable
[2025-10-17T08:41:59.317+0000] {subprocess.py:97} INFO - Command exited with return code 3
[2025-10-17T08:41:59.328+0000] {taskinstance.py:1937} ERROR - Task failed with exception
Traceback (most recent call last):
  File "/home/airflow/.local/lib/python3.8/site-packages/airflow/operators/bash.py", line 210, in execute
    raise AirflowException(
airflow.exceptions.AirflowException: Bash command failed. The command returned a non-zero exit code 3.
[2025-10-17T08:41:59.333+0000] {taskinstance.py:1400} INFO - Marking task as FAILED. dag_id=csv_etl_pipeline, task_id=soda_scan_2, execution_date=20251016T200000, start_date=20251017T084158, end_date=20251017T084159
[2025-10-17T08:41:59.344+0000] {standard_task_runner.py:104} ERROR - Failed to execute job 8 for task soda_scan_2 (Bash command failed. The command returned a non-zero exit code 3.; 105)
[2025-10-17T08:41:59.355+0000] {local_task_job_runner.py:228} INFO - Task exited with return code 1
[2025-10-17T08:41:59.369+0000] {taskinstance.py:2778} INFO - 0 downstream tasks scheduled from follow-on schedule check
[2025-10-17T08:44:13.776+0000] {taskinstance.py:1159} INFO - Dependencies all met for dep_context=non-requeueable deps ti=<TaskInstance: csv_etl_pipeline.soda_scan_2 scheduled__2025-10-16T20:00:00+00:00 [queued]>
[2025-10-17T08:44:13.784+0000] {taskinstance.py:1159} INFO - Dependencies all met for dep_context=requeueable deps ti=<TaskInstance: csv_etl_pipeline.soda_scan_2 scheduled__2025-10-16T20:00:00+00:00 [queued]>
[2025-10-17T08:44:13.784+0000] {taskinstance.py:1361} INFO - Starting attempt 1 of 1
[2025-10-17T08:44:13.796+0000] {taskinstance.py:1382} INFO - Executing <Task(BashOperator): soda_scan_2> on 2025-10-16 20:00:00+00:00
[2025-10-17T08:44:13.801+0000] {standard_task_runner.py:57} INFO - Started process 105 to run task
[2025-10-17T08:44:13.804+0000] {standard_task_runner.py:84} INFO - Running: ['***', 'tasks', 'run', 'csv_etl_pipeline', 'soda_scan_2', 'scheduled__2025-10-16T20:00:00+00:00', '--job-id', '8', '--raw', '--subdir', 'DAGS_FOLDER/etl.py', '--cfg-path', '/tmp/tmpgkwho1is']
[2025-10-17T08:44:13.807+0000] {standard_task_runner.py:85} INFO - Job 8: Subtask soda_scan_2
[2025-10-17T08:44:13.848+0000] {task_command.py:416} INFO - Running <TaskInstance: csv_etl_pipeline.soda_scan_2 scheduled__2025-10-16T20:00:00+00:00 [running]> on host 41c1f4dd29f1
[2025-10-17T08:44:13.908+0000] {taskinstance.py:1662} INFO - Exporting env vars: AIRFLOW_CTX_DAG_OWNER='***' AIRFLOW_CTX_DAG_ID='csv_etl_pipeline' AIRFLOW_CTX_TASK_ID='soda_scan_2' AIRFLOW_CTX_EXECUTION_DATE='2025-10-16T20:00:00+00:00' AIRFLOW_CTX_TRY_NUMBER='1' AIRFLOW_CTX_DAG_RUN_ID='scheduled__2025-10-16T20:00:00+00:00'
[2025-10-17T08:44:13.911+0000] {subprocess.py:63} INFO - Tmp dir root location: /tmp
[2025-10-17T08:44:13.912+0000] {subprocess.py:75} INFO - Running command: ['/bin/bash', '-c', 'soda scan -d ***_pg -c /opt/***/dags/soda/configuration.yml /opt/***/dags/soda/checks_2.yml']
[2025-10-17T08:44:13.926+0000] {subprocess.py:86} INFO - Output:
[2025-10-17T08:44:14.806+0000] {subprocess.py:93} INFO - [08:44:14] Soda Core 3.5.6
[2025-10-17T08:44:14.863+0000] {subprocess.py:93} INFO - [08:44:14] Could not add SodaCL file /opt/***/dags/soda/checks_2.yml
[2025-10-17T08:44:14.864+0000] {subprocess.py:93} INFO -   | 'NoneType' object is not iterable
[2025-10-17T08:44:14.877+0000] {subprocess.py:93} INFO - [08:44:14] Counting invalid without valid or invalid specification does not make sense. ("invalid_count(price) = 0" @ line=9,col=5 in /opt/***/dags/soda/checks_2.yml)
[2025-10-17T08:44:14.881+0000] {subprocess.py:93} INFO - [08:44:14] Scan summary:
[2025-10-17T08:44:14.881+0000] {subprocess.py:93} INFO - [08:44:14] 6/6 checks PASSED:
[2025-10-17T08:44:14.881+0000] {subprocess.py:93} INFO - [08:44:14]     games in ***_pg
[2025-10-17T08:44:14.881+0000] {subprocess.py:93} INFO - [08:44:14]       row_count > 0 [PASSED]
[2025-10-17T08:44:14.881+0000] {subprocess.py:93} INFO - [08:44:14]       missing_count(game) = 0 [PASSED]
[2025-10-17T08:44:14.881+0000] {subprocess.py:93} INFO - [08:44:14]       duplicate_count(urlgame) = 0 [PASSED]
[2025-10-17T08:44:14.881+0000] {subprocess.py:93} INFO - [08:44:14]     prices in ***_pg
[2025-10-17T08:44:14.882+0000] {subprocess.py:93} INFO - [08:44:14]       row_count > 0 [PASSED]
[2025-10-17T08:44:14.882+0000] {subprocess.py:93} INFO - [08:44:14]       missing_count(price) = 0 [PASSED]
[2025-10-17T08:44:14.882+0000] {subprocess.py:93} INFO - [08:44:14]       invalid_count(price) = 0 [PASSED]
[2025-10-17T08:44:14.882+0000] {subprocess.py:93} INFO - [08:44:14] 1 errors.
[2025-10-17T08:44:14.882+0000] {subprocess.py:93} INFO - [08:44:14] Oops! 1 error. 0 failures. 0 warnings. 6 pass.
[2025-10-17T08:44:14.882+0000] {subprocess.py:93} INFO - ERRORS:
[2025-10-17T08:44:14.882+0000] {subprocess.py:93} INFO - [08:44:14] Could not add SodaCL file /opt/***/dags/soda/checks_2.yml
[2025-10-17T08:44:14.882+0000] {subprocess.py:93} INFO -   | 'NoneType' object is not iterable
[2025-10-17T08:44:15.093+0000] {subprocess.py:97} INFO - Command exited with return code 3
[2025-10-17T08:44:15.102+0000] {taskinstance.py:1937} ERROR - Task failed with exception
Traceback (most recent call last):
  File "/home/airflow/.local/lib/python3.8/site-packages/airflow/operators/bash.py", line 210, in execute
    raise AirflowException(
airflow.exceptions.AirflowException: Bash command failed. The command returned a non-zero exit code 3.
[2025-10-17T08:44:15.105+0000] {taskinstance.py:1400} INFO - Marking task as FAILED. dag_id=csv_etl_pipeline, task_id=soda_scan_2, execution_date=20251016T200000, start_date=20251017T084413, end_date=20251017T084415
[2025-10-17T08:44:15.116+0000] {standard_task_runner.py:104} ERROR - Failed to execute job 8 for task soda_scan_2 (Bash command failed. The command returned a non-zero exit code 3.; 105)
[2025-10-17T08:44:15.140+0000] {local_task_job_runner.py:228} INFO - Task exited with return code 1
[2025-10-17T08:44:15.153+0000] {taskinstance.py:2778} INFO - 0 downstream tasks scheduled from follow-on schedule check
[2025-10-17T08:45:30.427+0000] {taskinstance.py:1159} INFO - Dependencies all met for dep_context=non-requeueable deps ti=<TaskInstance: csv_etl_pipeline.soda_scan_2 scheduled__2025-10-16T20:00:00+00:00 [queued]>
[2025-10-17T08:45:30.434+0000] {taskinstance.py:1159} INFO - Dependencies all met for dep_context=requeueable deps ti=<TaskInstance: csv_etl_pipeline.soda_scan_2 scheduled__2025-10-16T20:00:00+00:00 [queued]>
[2025-10-17T08:45:30.434+0000] {taskinstance.py:1361} INFO - Starting attempt 1 of 1
[2025-10-17T08:45:30.444+0000] {taskinstance.py:1382} INFO - Executing <Task(BashOperator): soda_scan_2> on 2025-10-16 20:00:00+00:00
[2025-10-17T08:45:30.450+0000] {standard_task_runner.py:57} INFO - Started process 105 to run task
[2025-10-17T08:45:30.453+0000] {standard_task_runner.py:84} INFO - Running: ['***', 'tasks', 'run', 'csv_etl_pipeline', 'soda_scan_2', 'scheduled__2025-10-16T20:00:00+00:00', '--job-id', '8', '--raw', '--subdir', 'DAGS_FOLDER/etl.py', '--cfg-path', '/tmp/tmpdaa66_5o']
[2025-10-17T08:45:30.456+0000] {standard_task_runner.py:85} INFO - Job 8: Subtask soda_scan_2
[2025-10-17T08:45:30.496+0000] {task_command.py:416} INFO - Running <TaskInstance: csv_etl_pipeline.soda_scan_2 scheduled__2025-10-16T20:00:00+00:00 [running]> on host e6d798efe4b0
[2025-10-17T08:45:30.561+0000] {taskinstance.py:1662} INFO - Exporting env vars: AIRFLOW_CTX_DAG_OWNER='***' AIRFLOW_CTX_DAG_ID='csv_etl_pipeline' AIRFLOW_CTX_TASK_ID='soda_scan_2' AIRFLOW_CTX_EXECUTION_DATE='2025-10-16T20:00:00+00:00' AIRFLOW_CTX_TRY_NUMBER='1' AIRFLOW_CTX_DAG_RUN_ID='scheduled__2025-10-16T20:00:00+00:00'
[2025-10-17T08:45:30.564+0000] {subprocess.py:63} INFO - Tmp dir root location: /tmp
[2025-10-17T08:45:30.564+0000] {subprocess.py:75} INFO - Running command: ['/bin/bash', '-c', 'soda scan -d ***_pg -c /opt/***/dags/soda/configuration.yml /opt/***/dags/soda/checks_2.yml']
[2025-10-17T08:45:30.578+0000] {subprocess.py:86} INFO - Output:
[2025-10-17T08:45:31.540+0000] {subprocess.py:93} INFO - [08:45:31] Soda Core 3.5.6
[2025-10-17T08:45:31.597+0000] {subprocess.py:93} INFO - [08:45:31] Could not add SodaCL file /opt/***/dags/soda/checks_2.yml
[2025-10-17T08:45:31.598+0000] {subprocess.py:93} INFO -   | 'NoneType' object is not iterable
[2025-10-17T08:45:31.614+0000] {subprocess.py:93} INFO - [08:45:31] Counting invalid without valid or invalid specification does not make sense. ("invalid_count(price) = 0" @ line=9,col=5 in /opt/***/dags/soda/checks_2.yml)
[2025-10-17T08:45:31.617+0000] {subprocess.py:93} INFO - [08:45:31] Scan summary:
[2025-10-17T08:45:31.617+0000] {subprocess.py:93} INFO - [08:45:31] 6/6 checks PASSED:
[2025-10-17T08:45:31.617+0000] {subprocess.py:93} INFO - [08:45:31]     games in ***_pg
[2025-10-17T08:45:31.617+0000] {subprocess.py:93} INFO - [08:45:31]       row_count > 0 [PASSED]
[2025-10-17T08:45:31.617+0000] {subprocess.py:93} INFO - [08:45:31]       missing_count(game) = 0 [PASSED]
[2025-10-17T08:45:31.617+0000] {subprocess.py:93} INFO - [08:45:31]       duplicate_count(urlgame) = 0 [PASSED]
[2025-10-17T08:45:31.617+0000] {subprocess.py:93} INFO - [08:45:31]     prices in ***_pg
[2025-10-17T08:45:31.618+0000] {subprocess.py:93} INFO - [08:45:31]       row_count > 0 [PASSED]
[2025-10-17T08:45:31.618+0000] {subprocess.py:93} INFO - [08:45:31]       missing_count(price) = 0 [PASSED]
[2025-10-17T08:45:31.618+0000] {subprocess.py:93} INFO - [08:45:31]       invalid_count(price) = 0 [PASSED]
[2025-10-17T08:45:31.618+0000] {subprocess.py:93} INFO - [08:45:31] 1 errors.
[2025-10-17T08:45:31.618+0000] {subprocess.py:93} INFO - [08:45:31] Oops! 1 error. 0 failures. 0 warnings. 6 pass.
[2025-10-17T08:45:31.618+0000] {subprocess.py:93} INFO - ERRORS:
[2025-10-17T08:45:31.618+0000] {subprocess.py:93} INFO - [08:45:31] Could not add SodaCL file /opt/***/dags/soda/checks_2.yml
[2025-10-17T08:45:31.618+0000] {subprocess.py:93} INFO -   | 'NoneType' object is not iterable
[2025-10-17T08:45:31.815+0000] {subprocess.py:97} INFO - Command exited with return code 3
[2025-10-17T08:45:31.826+0000] {taskinstance.py:1937} ERROR - Task failed with exception
Traceback (most recent call last):
  File "/home/airflow/.local/lib/python3.8/site-packages/airflow/operators/bash.py", line 210, in execute
    raise AirflowException(
airflow.exceptions.AirflowException: Bash command failed. The command returned a non-zero exit code 3.
[2025-10-17T08:45:31.830+0000] {taskinstance.py:1400} INFO - Marking task as FAILED. dag_id=csv_etl_pipeline, task_id=soda_scan_2, execution_date=20251016T200000, start_date=20251017T084530, end_date=20251017T084531
[2025-10-17T08:45:31.842+0000] {standard_task_runner.py:104} ERROR - Failed to execute job 8 for task soda_scan_2 (Bash command failed. The command returned a non-zero exit code 3.; 105)
[2025-10-17T08:45:31.868+0000] {local_task_job_runner.py:228} INFO - Task exited with return code 1
[2025-10-17T08:45:31.883+0000] {taskinstance.py:2778} INFO - 0 downstream tasks scheduled from follow-on schedule check
[2025-10-17T08:47:26.536+0000] {taskinstance.py:1159} INFO - Dependencies all met for dep_context=non-requeueable deps ti=<TaskInstance: csv_etl_pipeline.soda_scan_2 scheduled__2025-10-16T20:00:00+00:00 [queued]>
[2025-10-17T08:47:26.544+0000] {taskinstance.py:1159} INFO - Dependencies all met for dep_context=requeueable deps ti=<TaskInstance: csv_etl_pipeline.soda_scan_2 scheduled__2025-10-16T20:00:00+00:00 [queued]>
[2025-10-17T08:47:26.544+0000] {taskinstance.py:1361} INFO - Starting attempt 1 of 1
[2025-10-17T08:47:26.553+0000] {taskinstance.py:1382} INFO - Executing <Task(BashOperator): soda_scan_2> on 2025-10-16 20:00:00+00:00
[2025-10-17T08:47:26.559+0000] {standard_task_runner.py:57} INFO - Started process 105 to run task
[2025-10-17T08:47:26.562+0000] {standard_task_runner.py:84} INFO - Running: ['***', 'tasks', 'run', 'csv_etl_pipeline', 'soda_scan_2', 'scheduled__2025-10-16T20:00:00+00:00', '--job-id', '8', '--raw', '--subdir', 'DAGS_FOLDER/etl.py', '--cfg-path', '/tmp/tmp2ql7_nbc']
[2025-10-17T08:47:26.565+0000] {standard_task_runner.py:85} INFO - Job 8: Subtask soda_scan_2
[2025-10-17T08:47:26.606+0000] {task_command.py:416} INFO - Running <TaskInstance: csv_etl_pipeline.soda_scan_2 scheduled__2025-10-16T20:00:00+00:00 [running]> on host e39668730f63
[2025-10-17T08:47:26.667+0000] {taskinstance.py:1662} INFO - Exporting env vars: AIRFLOW_CTX_DAG_OWNER='***' AIRFLOW_CTX_DAG_ID='csv_etl_pipeline' AIRFLOW_CTX_TASK_ID='soda_scan_2' AIRFLOW_CTX_EXECUTION_DATE='2025-10-16T20:00:00+00:00' AIRFLOW_CTX_TRY_NUMBER='1' AIRFLOW_CTX_DAG_RUN_ID='scheduled__2025-10-16T20:00:00+00:00'
[2025-10-17T08:47:26.669+0000] {subprocess.py:63} INFO - Tmp dir root location: /tmp
[2025-10-17T08:47:26.669+0000] {subprocess.py:75} INFO - Running command: ['/bin/bash', '-c', 'soda scan -d ***_pg -c /opt/***/dags/soda/configuration.yml /opt/***/dags/soda/checks_2.yml']
[2025-10-17T08:47:26.680+0000] {subprocess.py:86} INFO - Output:
[2025-10-17T08:47:27.563+0000] {subprocess.py:93} INFO - [08:47:27] Soda Core 3.5.6
[2025-10-17T08:47:27.618+0000] {subprocess.py:93} INFO - [08:47:27] Could not add SodaCL file /opt/***/dags/soda/checks_2.yml
[2025-10-17T08:47:27.618+0000] {subprocess.py:93} INFO -   | 'NoneType' object is not iterable
[2025-10-17T08:47:27.634+0000] {subprocess.py:93} INFO - [08:47:27] Counting invalid without valid or invalid specification does not make sense. ("invalid_count(price) = 0" @ line=9,col=5 in /opt/***/dags/soda/checks_2.yml)
[2025-10-17T08:47:27.636+0000] {subprocess.py:93} INFO - [08:47:27] Scan summary:
[2025-10-17T08:47:27.636+0000] {subprocess.py:93} INFO - [08:47:27] 6/6 checks PASSED:
[2025-10-17T08:47:27.636+0000] {subprocess.py:93} INFO - [08:47:27]     games in ***_pg
[2025-10-17T08:47:27.636+0000] {subprocess.py:93} INFO - [08:47:27]       row_count > 0 [PASSED]
[2025-10-17T08:47:27.636+0000] {subprocess.py:93} INFO - [08:47:27]       missing_count(game) = 0 [PASSED]
[2025-10-17T08:47:27.636+0000] {subprocess.py:93} INFO - [08:47:27]       duplicate_count(urlgame) = 0 [PASSED]
[2025-10-17T08:47:27.636+0000] {subprocess.py:93} INFO - [08:47:27]     prices in ***_pg
[2025-10-17T08:47:27.637+0000] {subprocess.py:93} INFO - [08:47:27]       row_count > 0 [PASSED]
[2025-10-17T08:47:27.637+0000] {subprocess.py:93} INFO - [08:47:27]       missing_count(price) = 0 [PASSED]
[2025-10-17T08:47:27.637+0000] {subprocess.py:93} INFO - [08:47:27]       invalid_count(price) = 0 [PASSED]
[2025-10-17T08:47:27.637+0000] {subprocess.py:93} INFO - [08:47:27] 1 errors.
[2025-10-17T08:47:27.637+0000] {subprocess.py:93} INFO - [08:47:27] Oops! 1 error. 0 failures. 0 warnings. 6 pass.
[2025-10-17T08:47:27.637+0000] {subprocess.py:93} INFO - ERRORS:
[2025-10-17T08:47:27.637+0000] {subprocess.py:93} INFO - [08:47:27] Could not add SodaCL file /opt/***/dags/soda/checks_2.yml
[2025-10-17T08:47:27.637+0000] {subprocess.py:93} INFO -   | 'NoneType' object is not iterable
[2025-10-17T08:47:28.126+0000] {subprocess.py:97} INFO - Command exited with return code 3
[2025-10-17T08:47:28.136+0000] {taskinstance.py:1937} ERROR - Task failed with exception
Traceback (most recent call last):
  File "/home/airflow/.local/lib/python3.8/site-packages/airflow/operators/bash.py", line 210, in execute
    raise AirflowException(
airflow.exceptions.AirflowException: Bash command failed. The command returned a non-zero exit code 3.
[2025-10-17T08:47:28.139+0000] {taskinstance.py:1400} INFO - Marking task as FAILED. dag_id=csv_etl_pipeline, task_id=soda_scan_2, execution_date=20251016T200000, start_date=20251017T084726, end_date=20251017T084728
[2025-10-17T08:47:28.148+0000] {standard_task_runner.py:104} ERROR - Failed to execute job 8 for task soda_scan_2 (Bash command failed. The command returned a non-zero exit code 3.; 105)
[2025-10-17T08:47:28.180+0000] {local_task_job_runner.py:228} INFO - Task exited with return code 1
[2025-10-17T08:47:28.193+0000] {taskinstance.py:2778} INFO - 0 downstream tasks scheduled from follow-on schedule check
[2025-10-17T08:51:40.477+0000] {taskinstance.py:1159} INFO - Dependencies all met for dep_context=non-requeueable deps ti=<TaskInstance: csv_etl_pipeline.soda_scan_2 scheduled__2025-10-16T20:00:00+00:00 [queued]>
[2025-10-17T08:51:40.484+0000] {taskinstance.py:1159} INFO - Dependencies all met for dep_context=requeueable deps ti=<TaskInstance: csv_etl_pipeline.soda_scan_2 scheduled__2025-10-16T20:00:00+00:00 [queued]>
[2025-10-17T08:51:40.484+0000] {taskinstance.py:1361} INFO - Starting attempt 1 of 1
[2025-10-17T08:51:40.493+0000] {taskinstance.py:1382} INFO - Executing <Task(BashOperator): soda_scan_2> on 2025-10-16 20:00:00+00:00
[2025-10-17T08:51:40.499+0000] {standard_task_runner.py:57} INFO - Started process 105 to run task
[2025-10-17T08:51:40.502+0000] {standard_task_runner.py:84} INFO - Running: ['***', 'tasks', 'run', 'csv_etl_pipeline', 'soda_scan_2', 'scheduled__2025-10-16T20:00:00+00:00', '--job-id', '8', '--raw', '--subdir', 'DAGS_FOLDER/etl.py', '--cfg-path', '/tmp/tmplsngaty5']
[2025-10-17T08:51:40.505+0000] {standard_task_runner.py:85} INFO - Job 8: Subtask soda_scan_2
[2025-10-17T08:51:40.545+0000] {task_command.py:416} INFO - Running <TaskInstance: csv_etl_pipeline.soda_scan_2 scheduled__2025-10-16T20:00:00+00:00 [running]> on host 37d538dfd0b6
[2025-10-17T08:51:40.602+0000] {taskinstance.py:1662} INFO - Exporting env vars: AIRFLOW_CTX_DAG_OWNER='***' AIRFLOW_CTX_DAG_ID='csv_etl_pipeline' AIRFLOW_CTX_TASK_ID='soda_scan_2' AIRFLOW_CTX_EXECUTION_DATE='2025-10-16T20:00:00+00:00' AIRFLOW_CTX_TRY_NUMBER='1' AIRFLOW_CTX_DAG_RUN_ID='scheduled__2025-10-16T20:00:00+00:00'
[2025-10-17T08:51:40.604+0000] {subprocess.py:63} INFO - Tmp dir root location: /tmp
[2025-10-17T08:51:40.604+0000] {subprocess.py:75} INFO - Running command: ['/bin/bash', '-c', 'soda scan -d ***_pg -c /opt/***/dags/soda/configuration.yml /opt/***/dags/soda/checks_2.yml']
[2025-10-17T08:51:40.615+0000] {subprocess.py:86} INFO - Output:
[2025-10-17T08:51:41.432+0000] {subprocess.py:93} INFO - [08:51:41] Soda Core 3.5.6
[2025-10-17T08:51:41.482+0000] {subprocess.py:93} INFO - [08:51:41] Could not add SodaCL file /opt/***/dags/soda/checks_2.yml
[2025-10-17T08:51:41.482+0000] {subprocess.py:93} INFO -   | 'NoneType' object is not iterable
[2025-10-17T08:51:41.496+0000] {subprocess.py:93} INFO - [08:51:41] Counting invalid without valid or invalid specification does not make sense. ("invalid_count(price) = 0" @ line=9,col=5 in /opt/***/dags/soda/checks_2.yml)
[2025-10-17T08:51:41.498+0000] {subprocess.py:93} INFO - [08:51:41] Scan summary:
[2025-10-17T08:51:41.499+0000] {subprocess.py:93} INFO - [08:51:41] 6/6 checks PASSED:
[2025-10-17T08:51:41.499+0000] {subprocess.py:93} INFO - [08:51:41]     games in ***_pg
[2025-10-17T08:51:41.499+0000] {subprocess.py:93} INFO - [08:51:41]       row_count > 0 [PASSED]
[2025-10-17T08:51:41.499+0000] {subprocess.py:93} INFO - [08:51:41]       missing_count(game) = 0 [PASSED]
[2025-10-17T08:51:41.499+0000] {subprocess.py:93} INFO - [08:51:41]       duplicate_count(urlgame) = 0 [PASSED]
[2025-10-17T08:51:41.499+0000] {subprocess.py:93} INFO - [08:51:41]     prices in ***_pg
[2025-10-17T08:51:41.499+0000] {subprocess.py:93} INFO - [08:51:41]       row_count > 0 [PASSED]
[2025-10-17T08:51:41.499+0000] {subprocess.py:93} INFO - [08:51:41]       missing_count(price) = 0 [PASSED]
[2025-10-17T08:51:41.499+0000] {subprocess.py:93} INFO - [08:51:41]       invalid_count(price) = 0 [PASSED]
[2025-10-17T08:51:41.499+0000] {subprocess.py:93} INFO - [08:51:41] 1 errors.
[2025-10-17T08:51:41.499+0000] {subprocess.py:93} INFO - [08:51:41] Oops! 1 error. 0 failures. 0 warnings. 6 pass.
[2025-10-17T08:51:41.499+0000] {subprocess.py:93} INFO - ERRORS:
[2025-10-17T08:51:41.499+0000] {subprocess.py:93} INFO - [08:51:41] Could not add SodaCL file /opt/***/dags/soda/checks_2.yml
[2025-10-17T08:51:41.499+0000] {subprocess.py:93} INFO -   | 'NoneType' object is not iterable
[2025-10-17T08:51:41.696+0000] {subprocess.py:97} INFO - Command exited with return code 3
[2025-10-17T08:51:41.706+0000] {taskinstance.py:1937} ERROR - Task failed with exception
Traceback (most recent call last):
  File "/home/airflow/.local/lib/python3.8/site-packages/airflow/operators/bash.py", line 210, in execute
    raise AirflowException(
airflow.exceptions.AirflowException: Bash command failed. The command returned a non-zero exit code 3.
[2025-10-17T08:51:41.709+0000] {taskinstance.py:1400} INFO - Marking task as FAILED. dag_id=csv_etl_pipeline, task_id=soda_scan_2, execution_date=20251016T200000, start_date=20251017T085140, end_date=20251017T085141
[2025-10-17T08:51:41.720+0000] {standard_task_runner.py:104} ERROR - Failed to execute job 8 for task soda_scan_2 (Bash command failed. The command returned a non-zero exit code 3.; 105)
[2025-10-17T08:51:41.759+0000] {local_task_job_runner.py:228} INFO - Task exited with return code 1
[2025-10-17T08:51:41.772+0000] {taskinstance.py:2778} INFO - 0 downstream tasks scheduled from follow-on schedule check
[2025-10-17T08:55:00.025+0000] {taskinstance.py:1159} INFO - Dependencies all met for dep_context=non-requeueable deps ti=<TaskInstance: csv_etl_pipeline.soda_scan_2 scheduled__2025-10-16T20:00:00+00:00 [queued]>
[2025-10-17T08:55:00.033+0000] {taskinstance.py:1159} INFO - Dependencies all met for dep_context=requeueable deps ti=<TaskInstance: csv_etl_pipeline.soda_scan_2 scheduled__2025-10-16T20:00:00+00:00 [queued]>
[2025-10-17T08:55:00.033+0000] {taskinstance.py:1361} INFO - Starting attempt 1 of 1
[2025-10-17T08:55:00.042+0000] {taskinstance.py:1382} INFO - Executing <Task(BashOperator): soda_scan_2> on 2025-10-16 20:00:00+00:00
[2025-10-17T08:55:00.047+0000] {standard_task_runner.py:57} INFO - Started process 97 to run task
[2025-10-17T08:55:00.050+0000] {standard_task_runner.py:84} INFO - Running: ['***', 'tasks', 'run', 'csv_etl_pipeline', 'soda_scan_2', 'scheduled__2025-10-16T20:00:00+00:00', '--job-id', '8', '--raw', '--subdir', 'DAGS_FOLDER/etl.py', '--cfg-path', '/tmp/tmpyk30i9v_']
[2025-10-17T08:55:00.053+0000] {standard_task_runner.py:85} INFO - Job 8: Subtask soda_scan_2
[2025-10-17T08:55:00.098+0000] {task_command.py:416} INFO - Running <TaskInstance: csv_etl_pipeline.soda_scan_2 scheduled__2025-10-16T20:00:00+00:00 [running]> on host 7a3806afa772
[2025-10-17T08:55:00.160+0000] {taskinstance.py:1662} INFO - Exporting env vars: AIRFLOW_CTX_DAG_OWNER='***' AIRFLOW_CTX_DAG_ID='csv_etl_pipeline' AIRFLOW_CTX_TASK_ID='soda_scan_2' AIRFLOW_CTX_EXECUTION_DATE='2025-10-16T20:00:00+00:00' AIRFLOW_CTX_TRY_NUMBER='1' AIRFLOW_CTX_DAG_RUN_ID='scheduled__2025-10-16T20:00:00+00:00'
[2025-10-17T08:55:00.162+0000] {subprocess.py:63} INFO - Tmp dir root location: /tmp
[2025-10-17T08:55:00.162+0000] {subprocess.py:75} INFO - Running command: ['/bin/bash', '-c', 'soda scan -d ***_pg -c /opt/***/dags/soda/configuration.yml /opt/***/dags/soda/checks_2.yml']
[2025-10-17T08:55:00.173+0000] {subprocess.py:86} INFO - Output:
[2025-10-17T08:55:00.960+0000] {subprocess.py:93} INFO - [08:55:00] Soda Core 3.5.6
[2025-10-17T08:55:01.008+0000] {subprocess.py:93} INFO - [08:55:01] Could not add SodaCL file /opt/***/dags/soda/checks_2.yml
[2025-10-17T08:55:01.008+0000] {subprocess.py:93} INFO -   | 'NoneType' object is not iterable
[2025-10-17T08:55:01.022+0000] {subprocess.py:93} INFO - [08:55:01] Counting invalid without valid or invalid specification does not make sense. ("invalid_count(price) = 0" @ line=9,col=5 in /opt/***/dags/soda/checks_2.yml)
[2025-10-17T08:55:01.024+0000] {subprocess.py:93} INFO - [08:55:01] Scan summary:
[2025-10-17T08:55:01.024+0000] {subprocess.py:93} INFO - [08:55:01] 6/6 checks PASSED:
[2025-10-17T08:55:01.024+0000] {subprocess.py:93} INFO - [08:55:01]     games in ***_pg
[2025-10-17T08:55:01.024+0000] {subprocess.py:93} INFO - [08:55:01]       row_count > 0 [PASSED]
[2025-10-17T08:55:01.024+0000] {subprocess.py:93} INFO - [08:55:01]       missing_count(game) = 0 [PASSED]
[2025-10-17T08:55:01.024+0000] {subprocess.py:93} INFO - [08:55:01]       duplicate_count(urlgame) = 0 [PASSED]
[2025-10-17T08:55:01.025+0000] {subprocess.py:93} INFO - [08:55:01]     prices in ***_pg
[2025-10-17T08:55:01.025+0000] {subprocess.py:93} INFO - [08:55:01]       row_count > 0 [PASSED]
[2025-10-17T08:55:01.025+0000] {subprocess.py:93} INFO - [08:55:01]       missing_count(price) = 0 [PASSED]
[2025-10-17T08:55:01.025+0000] {subprocess.py:93} INFO - [08:55:01]       invalid_count(price) = 0 [PASSED]
[2025-10-17T08:55:01.025+0000] {subprocess.py:93} INFO - [08:55:01] 1 errors.
[2025-10-17T08:55:01.025+0000] {subprocess.py:93} INFO - [08:55:01] Oops! 1 error. 0 failures. 0 warnings. 6 pass.
[2025-10-17T08:55:01.025+0000] {subprocess.py:93} INFO - ERRORS:
[2025-10-17T08:55:01.025+0000] {subprocess.py:93} INFO - [08:55:01] Could not add SodaCL file /opt/***/dags/soda/checks_2.yml
[2025-10-17T08:55:01.025+0000] {subprocess.py:93} INFO -   | 'NoneType' object is not iterable
[2025-10-17T08:55:01.260+0000] {subprocess.py:97} INFO - Command exited with return code 3
[2025-10-17T08:55:01.272+0000] {taskinstance.py:1937} ERROR - Task failed with exception
Traceback (most recent call last):
  File "/home/airflow/.local/lib/python3.8/site-packages/airflow/operators/bash.py", line 210, in execute
    raise AirflowException(
airflow.exceptions.AirflowException: Bash command failed. The command returned a non-zero exit code 3.
[2025-10-17T08:55:01.275+0000] {taskinstance.py:1400} INFO - Marking task as FAILED. dag_id=csv_etl_pipeline, task_id=soda_scan_2, execution_date=20251016T200000, start_date=20251017T085500, end_date=20251017T085501
[2025-10-17T08:55:01.285+0000] {standard_task_runner.py:104} ERROR - Failed to execute job 8 for task soda_scan_2 (Bash command failed. The command returned a non-zero exit code 3.; 97)
[2025-10-17T08:55:01.307+0000] {local_task_job_runner.py:228} INFO - Task exited with return code 1
[2025-10-17T08:55:01.321+0000] {taskinstance.py:2778} INFO - 0 downstream tasks scheduled from follow-on schedule check
[2025-10-17T09:02:40.449+0000] {taskinstance.py:1159} INFO - Dependencies all met for dep_context=non-requeueable deps ti=<TaskInstance: csv_etl_pipeline.soda_scan_2 scheduled__2025-10-16T20:00:00+00:00 [queued]>
[2025-10-17T09:02:40.458+0000] {taskinstance.py:1159} INFO - Dependencies all met for dep_context=requeueable deps ti=<TaskInstance: csv_etl_pipeline.soda_scan_2 scheduled__2025-10-16T20:00:00+00:00 [queued]>
[2025-10-17T09:02:40.458+0000] {taskinstance.py:1361} INFO - Starting attempt 1 of 1
[2025-10-17T09:02:40.471+0000] {taskinstance.py:1382} INFO - Executing <Task(BashOperator): soda_scan_2> on 2025-10-16 20:00:00+00:00
[2025-10-17T09:02:40.476+0000] {standard_task_runner.py:57} INFO - Started process 97 to run task
[2025-10-17T09:02:40.480+0000] {standard_task_runner.py:84} INFO - Running: ['***', 'tasks', 'run', 'csv_etl_pipeline', 'soda_scan_2', 'scheduled__2025-10-16T20:00:00+00:00', '--job-id', '8', '--raw', '--subdir', 'DAGS_FOLDER/etl.py', '--cfg-path', '/tmp/tmpdddcolhz']
[2025-10-17T09:02:40.483+0000] {standard_task_runner.py:85} INFO - Job 8: Subtask soda_scan_2
[2025-10-17T09:02:40.525+0000] {task_command.py:416} INFO - Running <TaskInstance: csv_etl_pipeline.soda_scan_2 scheduled__2025-10-16T20:00:00+00:00 [running]> on host 53e08e0285d6
[2025-10-17T09:02:40.586+0000] {taskinstance.py:1662} INFO - Exporting env vars: AIRFLOW_CTX_DAG_OWNER='***' AIRFLOW_CTX_DAG_ID='csv_etl_pipeline' AIRFLOW_CTX_TASK_ID='soda_scan_2' AIRFLOW_CTX_EXECUTION_DATE='2025-10-16T20:00:00+00:00' AIRFLOW_CTX_TRY_NUMBER='1' AIRFLOW_CTX_DAG_RUN_ID='scheduled__2025-10-16T20:00:00+00:00'
[2025-10-17T09:02:40.588+0000] {subprocess.py:63} INFO - Tmp dir root location: /tmp
[2025-10-17T09:02:40.589+0000] {subprocess.py:75} INFO - Running command: ['/bin/bash', '-c', 'soda scan -d ***_pg -c /opt/***/dags/soda/configuration.yml /opt/***/dags/soda/checks_2.yml']
[2025-10-17T09:02:40.600+0000] {subprocess.py:86} INFO - Output:
[2025-10-17T09:02:41.509+0000] {subprocess.py:93} INFO - [09:02:41] Soda Core 3.5.6
[2025-10-17T09:02:41.589+0000] {subprocess.py:93} INFO - [09:02:41] Could not add SodaCL file /opt/***/dags/soda/checks_2.yml
[2025-10-17T09:02:41.590+0000] {subprocess.py:93} INFO -   | 'NoneType' object is not iterable
[2025-10-17T09:02:41.617+0000] {subprocess.py:93} INFO - [09:02:41] Counting invalid without valid or invalid specification does not make sense. ("invalid_count(price) = 0" @ line=9,col=5 in /opt/***/dags/soda/checks_2.yml)
[2025-10-17T09:02:41.621+0000] {subprocess.py:93} INFO - [09:02:41] Scan summary:
[2025-10-17T09:02:41.621+0000] {subprocess.py:93} INFO - [09:02:41] 6/6 checks PASSED:
[2025-10-17T09:02:41.621+0000] {subprocess.py:93} INFO - [09:02:41]     games in ***_pg
[2025-10-17T09:02:41.622+0000] {subprocess.py:93} INFO - [09:02:41]       row_count > 0 [PASSED]
[2025-10-17T09:02:41.622+0000] {subprocess.py:93} INFO - [09:02:41]       missing_count(game) = 0 [PASSED]
[2025-10-17T09:02:41.622+0000] {subprocess.py:93} INFO - [09:02:41]       duplicate_count(urlgame) = 0 [PASSED]
[2025-10-17T09:02:41.622+0000] {subprocess.py:93} INFO - [09:02:41]     prices in ***_pg
[2025-10-17T09:02:41.622+0000] {subprocess.py:93} INFO - [09:02:41]       row_count > 0 [PASSED]
[2025-10-17T09:02:41.622+0000] {subprocess.py:93} INFO - [09:02:41]       missing_count(price) = 0 [PASSED]
[2025-10-17T09:02:41.622+0000] {subprocess.py:93} INFO - [09:02:41]       invalid_count(price) = 0 [PASSED]
[2025-10-17T09:02:41.623+0000] {subprocess.py:93} INFO - [09:02:41] 1 errors.
[2025-10-17T09:02:41.623+0000] {subprocess.py:93} INFO - [09:02:41] Oops! 1 error. 0 failures. 0 warnings. 6 pass.
[2025-10-17T09:02:41.623+0000] {subprocess.py:93} INFO - ERRORS:
[2025-10-17T09:02:41.623+0000] {subprocess.py:93} INFO - [09:02:41] Could not add SodaCL file /opt/***/dags/soda/checks_2.yml
[2025-10-17T09:02:41.623+0000] {subprocess.py:93} INFO -   | 'NoneType' object is not iterable
[2025-10-17T09:02:41.908+0000] {subprocess.py:97} INFO - Command exited with return code 3
[2025-10-17T09:02:41.920+0000] {taskinstance.py:1937} ERROR - Task failed with exception
Traceback (most recent call last):
  File "/home/airflow/.local/lib/python3.8/site-packages/airflow/operators/bash.py", line 210, in execute
    raise AirflowException(
airflow.exceptions.AirflowException: Bash command failed. The command returned a non-zero exit code 3.
[2025-10-17T09:02:41.924+0000] {taskinstance.py:1400} INFO - Marking task as FAILED. dag_id=csv_etl_pipeline, task_id=soda_scan_2, execution_date=20251016T200000, start_date=20251017T090240, end_date=20251017T090241
[2025-10-17T09:02:41.939+0000] {standard_task_runner.py:104} ERROR - Failed to execute job 8 for task soda_scan_2 (Bash command failed. The command returned a non-zero exit code 3.; 97)
[2025-10-17T09:02:41.977+0000] {local_task_job_runner.py:228} INFO - Task exited with return code 1
[2025-10-17T09:02:41.997+0000] {taskinstance.py:2778} INFO - 0 downstream tasks scheduled from follow-on schedule check
[2025-10-17T09:09:12.497+0000] {taskinstance.py:1159} INFO - Dependencies all met for dep_context=non-requeueable deps ti=<TaskInstance: csv_etl_pipeline.soda_scan_2 scheduled__2025-10-16T20:00:00+00:00 [queued]>
[2025-10-17T09:09:12.504+0000] {taskinstance.py:1159} INFO - Dependencies all met for dep_context=requeueable deps ti=<TaskInstance: csv_etl_pipeline.soda_scan_2 scheduled__2025-10-16T20:00:00+00:00 [queued]>
[2025-10-17T09:09:12.505+0000] {taskinstance.py:1361} INFO - Starting attempt 1 of 1
[2025-10-17T09:09:12.514+0000] {taskinstance.py:1382} INFO - Executing <Task(BashOperator): soda_scan_2> on 2025-10-16 20:00:00+00:00
[2025-10-17T09:09:12.519+0000] {standard_task_runner.py:57} INFO - Started process 109 to run task
[2025-10-17T09:09:12.524+0000] {standard_task_runner.py:84} INFO - Running: ['***', 'tasks', 'run', 'csv_etl_pipeline', 'soda_scan_2', 'scheduled__2025-10-16T20:00:00+00:00', '--job-id', '9', '--raw', '--subdir', 'DAGS_FOLDER/etl.py', '--cfg-path', '/tmp/tmppxff5301']
[2025-10-17T09:09:12.527+0000] {standard_task_runner.py:85} INFO - Job 9: Subtask soda_scan_2
[2025-10-17T09:09:12.574+0000] {task_command.py:416} INFO - Running <TaskInstance: csv_etl_pipeline.soda_scan_2 scheduled__2025-10-16T20:00:00+00:00 [running]> on host 0c9ee2dc6164
[2025-10-17T09:09:12.637+0000] {taskinstance.py:1662} INFO - Exporting env vars: AIRFLOW_CTX_DAG_OWNER='***' AIRFLOW_CTX_DAG_ID='csv_etl_pipeline' AIRFLOW_CTX_TASK_ID='soda_scan_2' AIRFLOW_CTX_EXECUTION_DATE='2025-10-16T20:00:00+00:00' AIRFLOW_CTX_TRY_NUMBER='1' AIRFLOW_CTX_DAG_RUN_ID='scheduled__2025-10-16T20:00:00+00:00'
[2025-10-17T09:09:12.639+0000] {subprocess.py:63} INFO - Tmp dir root location: /tmp
[2025-10-17T09:09:12.640+0000] {subprocess.py:75} INFO - Running command: ['/bin/bash', '-c', 'soda scan -d ***_pg -c /opt/***/dags/soda/configuration.yml /opt/***/dags/soda/checks_2.yml']
[2025-10-17T09:09:12.651+0000] {subprocess.py:86} INFO - Output:
[2025-10-17T09:09:13.721+0000] {subprocess.py:93} INFO - [09:09:13] Soda Core 3.5.6
[2025-10-17T09:09:13.777+0000] {subprocess.py:93} INFO - [09:09:13] Could not add SodaCL file /opt/***/dags/soda/checks_2.yml
[2025-10-17T09:09:13.778+0000] {subprocess.py:93} INFO -   | 'NoneType' object is not iterable
[2025-10-17T09:09:13.798+0000] {subprocess.py:93} INFO - [09:09:13] Counting invalid without valid or invalid specification does not make sense. ("invalid_count(price) = 0" @ line=9,col=5 in /opt/***/dags/soda/checks_2.yml)
[2025-10-17T09:09:13.803+0000] {subprocess.py:93} INFO - [09:09:13] Scan summary:
[2025-10-17T09:09:13.804+0000] {subprocess.py:93} INFO - [09:09:13] 6/6 checks PASSED:
[2025-10-17T09:09:13.804+0000] {subprocess.py:93} INFO - [09:09:13]     games in ***_pg
[2025-10-17T09:09:13.804+0000] {subprocess.py:93} INFO - [09:09:13]       row_count > 0 [PASSED]
[2025-10-17T09:09:13.804+0000] {subprocess.py:93} INFO - [09:09:13]       missing_count(game) = 0 [PASSED]
[2025-10-17T09:09:13.804+0000] {subprocess.py:93} INFO - [09:09:13]       duplicate_count(urlgame) = 0 [PASSED]
[2025-10-17T09:09:13.804+0000] {subprocess.py:93} INFO - [09:09:13]     prices in ***_pg
[2025-10-17T09:09:13.804+0000] {subprocess.py:93} INFO - [09:09:13]       row_count > 0 [PASSED]
[2025-10-17T09:09:13.804+0000] {subprocess.py:93} INFO - [09:09:13]       missing_count(price) = 0 [PASSED]
[2025-10-17T09:09:13.804+0000] {subprocess.py:93} INFO - [09:09:13]       invalid_count(price) = 0 [PASSED]
[2025-10-17T09:09:13.804+0000] {subprocess.py:93} INFO - [09:09:13] 1 errors.
[2025-10-17T09:09:13.804+0000] {subprocess.py:93} INFO - [09:09:13] Oops! 1 error. 0 failures. 0 warnings. 6 pass.
[2025-10-17T09:09:13.804+0000] {subprocess.py:93} INFO - ERRORS:
[2025-10-17T09:09:13.804+0000] {subprocess.py:93} INFO - [09:09:13] Could not add SodaCL file /opt/***/dags/soda/checks_2.yml
[2025-10-17T09:09:13.804+0000] {subprocess.py:93} INFO -   | 'NoneType' object is not iterable
[2025-10-17T09:09:14.016+0000] {subprocess.py:97} INFO - Command exited with return code 3
[2025-10-17T09:09:14.025+0000] {taskinstance.py:1937} ERROR - Task failed with exception
Traceback (most recent call last):
  File "/home/airflow/.local/lib/python3.8/site-packages/airflow/operators/bash.py", line 210, in execute
    raise AirflowException(
airflow.exceptions.AirflowException: Bash command failed. The command returned a non-zero exit code 3.
[2025-10-17T09:09:14.028+0000] {taskinstance.py:1400} INFO - Marking task as FAILED. dag_id=csv_etl_pipeline, task_id=soda_scan_2, execution_date=20251016T200000, start_date=20251017T090912, end_date=20251017T090914
[2025-10-17T09:09:14.039+0000] {standard_task_runner.py:104} ERROR - Failed to execute job 9 for task soda_scan_2 (Bash command failed. The command returned a non-zero exit code 3.; 109)
[2025-10-17T09:09:14.061+0000] {local_task_job_runner.py:228} INFO - Task exited with return code 1
[2025-10-17T09:09:14.076+0000] {taskinstance.py:2778} INFO - 0 downstream tasks scheduled from follow-on schedule check
