[2025-10-16T13:22:49.964+0000] {taskinstance.py:1103} INFO - Dependencies all met for dep_context=non-requeueable deps ti=<TaskInstance: csv_etl_pipeline.load_data manual__2025-10-16T13:22:42.257871+00:00 [queued]>
[2025-10-16T13:22:49.975+0000] {taskinstance.py:1103} INFO - Dependencies all met for dep_context=requeueable deps ti=<TaskInstance: csv_etl_pipeline.load_data manual__2025-10-16T13:22:42.257871+00:00 [queued]>
[2025-10-16T13:22:49.975+0000] {taskinstance.py:1308} INFO - Starting attempt 1 of 1
[2025-10-16T13:22:49.988+0000] {taskinstance.py:1327} INFO - Executing <Task(PythonOperator): load_data> on 2025-10-16 13:22:42.257871+00:00
[2025-10-16T13:22:49.994+0000] {standard_task_runner.py:57} INFO - Started process 121 to run task
[2025-10-16T13:22:49.999+0000] {standard_task_runner.py:84} INFO - Running: ['***', 'tasks', 'run', 'csv_etl_pipeline', 'load_data', 'manual__2025-10-16T13:22:42.257871+00:00', '--job-id', '14', '--raw', '--subdir', 'DAGS_FOLDER/etl.py', '--cfg-path', '/tmp/tmpjdcwl9yq']
[2025-10-16T13:22:49.999+0000] {standard_task_runner.py:85} INFO - Job 14: Subtask load_data
[2025-10-16T13:22:50.049+0000] {task_command.py:410} INFO - Running <TaskInstance: csv_etl_pipeline.load_data manual__2025-10-16T13:22:42.257871+00:00 [running]> on host 252b671eecea
[2025-10-16T13:22:50.123+0000] {taskinstance.py:1547} INFO - Exporting env vars: AIRFLOW_CTX_DAG_OWNER='***' AIRFLOW_CTX_DAG_ID='csv_etl_pipeline' AIRFLOW_CTX_TASK_ID='load_data' AIRFLOW_CTX_EXECUTION_DATE='2025-10-16T13:22:42.257871+00:00' AIRFLOW_CTX_TRY_NUMBER='1' AIRFLOW_CTX_DAG_RUN_ID='manual__2025-10-16T13:22:42.257871+00:00'
[2025-10-16T13:22:50.151+0000] {taskinstance.py:1824} ERROR - Task failed with exception
Traceback (most recent call last):
  File "/home/airflow/.local/lib/python3.7/site-packages/airflow/operators/python.py", line 181, in execute
    return_value = self.execute_callable()
  File "/home/airflow/.local/lib/python3.7/site-packages/airflow/operators/python.py", line 198, in execute_callable
    return self.python_callable(*self.op_args, **self.op_kwargs)
  File "/opt/airflow/dags/etl.py", line 190, in load_data
    load_to_db(df)
  File "/opt/airflow/dags/etl.py", line 102, in load_to_db
    row['logdate']
psycopg2.errors.DatatypeMismatch: column "dateprice" is of type timestamp without time zone but expression is of type numeric
LINE 3:             VALUES (1.0, 6.65, 1760620967048.0)
                                       ^
HINT:  You will need to rewrite or cast the expression.

[2025-10-16T13:22:50.159+0000] {taskinstance.py:1350} INFO - Marking task as FAILED. dag_id=csv_etl_pipeline, task_id=load_data, execution_date=20251016T132242, start_date=20251016T132249, end_date=20251016T132250
[2025-10-16T13:22:50.169+0000] {standard_task_runner.py:109} ERROR - Failed to execute job 14 for task load_data (column "dateprice" is of type timestamp without time zone but expression is of type numeric
LINE 3:             VALUES (1.0, 6.65, 1760620967048.0)
                                       ^
HINT:  You will need to rewrite or cast the expression.
; 121)
[2025-10-16T13:22:50.210+0000] {local_task_job_runner.py:225} INFO - Task exited with return code 1
[2025-10-16T13:22:50.225+0000] {taskinstance.py:2651} INFO - 0 downstream tasks scheduled from follow-on schedule check
