[2025-10-16T13:11:02.808+0000] {taskinstance.py:1103} INFO - Dependencies all met for dep_context=non-requeueable deps ti=<TaskInstance: csv_etl_pipeline.request_api scheduled__2025-10-16T13:10:00+00:00 [queued]>
[2025-10-16T13:11:02.816+0000] {taskinstance.py:1103} INFO - Dependencies all met for dep_context=requeueable deps ti=<TaskInstance: csv_etl_pipeline.request_api scheduled__2025-10-16T13:10:00+00:00 [queued]>
[2025-10-16T13:11:02.816+0000] {taskinstance.py:1308} INFO - Starting attempt 1 of 1
[2025-10-16T13:11:02.828+0000] {taskinstance.py:1327} INFO - Executing <Task(PythonOperator): request_api> on 2025-10-16 13:10:00+00:00
[2025-10-16T13:11:02.834+0000] {standard_task_runner.py:57} INFO - Started process 122 to run task
[2025-10-16T13:11:02.837+0000] {standard_task_runner.py:84} INFO - Running: ['***', 'tasks', 'run', 'csv_etl_pipeline', 'request_api', 'scheduled__2025-10-16T13:10:00+00:00', '--job-id', '8', '--raw', '--subdir', 'DAGS_FOLDER/etl.py', '--cfg-path', '/tmp/tmp5h3vljl4']
[2025-10-16T13:11:02.838+0000] {standard_task_runner.py:85} INFO - Job 8: Subtask request_api
[2025-10-16T13:11:02.889+0000] {task_command.py:410} INFO - Running <TaskInstance: csv_etl_pipeline.request_api scheduled__2025-10-16T13:10:00+00:00 [running]> on host 98254aa9055c
[2025-10-16T13:11:02.960+0000] {taskinstance.py:1547} INFO - Exporting env vars: AIRFLOW_CTX_DAG_OWNER='***' AIRFLOW_CTX_DAG_ID='csv_etl_pipeline' AIRFLOW_CTX_TASK_ID='request_api' AIRFLOW_CTX_EXECUTION_DATE='2025-10-16T13:10:00+00:00' AIRFLOW_CTX_TRY_NUMBER='1' AIRFLOW_CTX_DAG_RUN_ID='scheduled__2025-10-16T13:10:00+00:00'
[2025-10-16T13:11:02.973+0000] {logging_mixin.py:149} INFO - None
[2025-10-16T13:11:02.975+0000] {taskinstance.py:1824} ERROR - Task failed with exception
Traceback (most recent call last):
  File "/home/airflow/.local/lib/python3.7/site-packages/airflow/operators/python.py", line 181, in execute
    return_value = self.execute_callable()
  File "/home/airflow/.local/lib/python3.7/site-packages/airflow/operators/python.py", line 198, in execute_callable
    return self.python_callable(*self.op_args, **self.op_kwargs)
  File "/opt/airflow/dags/etl.py", line 119, in request_api
    df = pd.read_json(StringIO(data))
  File "/home/airflow/.local/lib/python3.7/site-packages/pandas/util/_decorators.py", line 207, in wrapper
    return func(*args, **kwargs)
  File "/home/airflow/.local/lib/python3.7/site-packages/pandas/util/_decorators.py", line 311, in wrapper
    return func(*args, **kwargs)
  File "/home/airflow/.local/lib/python3.7/site-packages/pandas/io/json/_json.py", line 614, in read_json
    return json_reader.read()
  File "/home/airflow/.local/lib/python3.7/site-packages/pandas/io/json/_json.py", line 748, in read
    obj = self._get_object_parser(self.data)
  File "/home/airflow/.local/lib/python3.7/site-packages/pandas/io/json/_json.py", line 770, in _get_object_parser
    obj = FrameParser(json, **kwargs).parse()
  File "/home/airflow/.local/lib/python3.7/site-packages/pandas/io/json/_json.py", line 885, in parse
    self._parse_no_numpy()
  File "/home/airflow/.local/lib/python3.7/site-packages/pandas/io/json/_json.py", line 1140, in _parse_no_numpy
    loads(json, precise_float=self.precise_float), dtype=None
ValueError: Expected object or value
[2025-10-16T13:11:02.983+0000] {taskinstance.py:1350} INFO - Marking task as FAILED. dag_id=csv_etl_pipeline, task_id=request_api, execution_date=20251016T131000, start_date=20251016T131102, end_date=20251016T131102
[2025-10-16T13:11:02.993+0000] {standard_task_runner.py:109} ERROR - Failed to execute job 8 for task request_api (Expected object or value; 122)
[2025-10-16T13:11:03.009+0000] {local_task_job_runner.py:225} INFO - Task exited with return code 1
[2025-10-16T13:11:03.030+0000] {taskinstance.py:2651} INFO - 0 downstream tasks scheduled from follow-on schedule check
