[2025-10-16T14:27:05.108+0000] {taskinstance.py:1103} INFO - Dependencies all met for dep_context=non-requeueable deps ti=<TaskInstance: csv_etl_pipeline.soda_scan scheduled__2025-10-15T20:00:00+00:00 [queued]>
[2025-10-16T14:27:05.116+0000] {taskinstance.py:1103} INFO - Dependencies all met for dep_context=requeueable deps ti=<TaskInstance: csv_etl_pipeline.soda_scan scheduled__2025-10-15T20:00:00+00:00 [queued]>
[2025-10-16T14:27:05.117+0000] {taskinstance.py:1308} INFO - Starting attempt 1 of 1
[2025-10-16T14:27:05.131+0000] {taskinstance.py:1327} INFO - Executing <Task(BashOperator): soda_scan> on 2025-10-15 20:00:00+00:00
[2025-10-16T14:27:05.137+0000] {standard_task_runner.py:57} INFO - Started process 89 to run task
[2025-10-16T14:27:05.140+0000] {standard_task_runner.py:84} INFO - Running: ['***', 'tasks', 'run', 'csv_etl_pipeline', 'soda_scan', 'scheduled__2025-10-15T20:00:00+00:00', '--job-id', '6', '--raw', '--subdir', 'DAGS_FOLDER/etl.py', '--cfg-path', '/tmp/tmpyq5p012q']
[2025-10-16T14:27:05.141+0000] {standard_task_runner.py:85} INFO - Job 6: Subtask soda_scan
[2025-10-16T14:27:05.187+0000] {task_command.py:410} INFO - Running <TaskInstance: csv_etl_pipeline.soda_scan scheduled__2025-10-15T20:00:00+00:00 [running]> on host e072a881a620
[2025-10-16T14:27:05.263+0000] {taskinstance.py:1547} INFO - Exporting env vars: AIRFLOW_CTX_DAG_OWNER='***' AIRFLOW_CTX_DAG_ID='csv_etl_pipeline' AIRFLOW_CTX_TASK_ID='soda_scan' AIRFLOW_CTX_EXECUTION_DATE='2025-10-15T20:00:00+00:00' AIRFLOW_CTX_TRY_NUMBER='1' AIRFLOW_CTX_DAG_RUN_ID='scheduled__2025-10-15T20:00:00+00:00'
[2025-10-16T14:27:05.267+0000] {subprocess.py:63} INFO - Tmp dir root location: 
 /tmp
[2025-10-16T14:27:05.268+0000] {subprocess.py:75} INFO - Running command: ['/bin/bash', '-c', 'soda scan -d ***_pg -c /opt/***/dags/soda/configuration.yml /opt/***/dags/soda/checks.yml']
[2025-10-16T14:27:05.290+0000] {subprocess.py:86} INFO - Output:
[2025-10-16T14:27:05.295+0000] {subprocess.py:93} INFO - /bin/bash: line 1: soda: command not found
[2025-10-16T14:27:05.296+0000] {subprocess.py:97} INFO - Command exited with return code 127
[2025-10-16T14:27:05.307+0000] {taskinstance.py:1824} ERROR - Task failed with exception
Traceback (most recent call last):
  File "/home/airflow/.local/lib/python3.7/site-packages/airflow/operators/bash.py", line 211, in execute
    f"Bash command failed. The command returned a non-zero exit code {result.exit_code}."
airflow.exceptions.AirflowException: Bash command failed. The command returned a non-zero exit code 127.
[2025-10-16T14:27:05.311+0000] {taskinstance.py:1350} INFO - Marking task as FAILED. dag_id=csv_etl_pipeline, task_id=soda_scan, execution_date=20251015T200000, start_date=20251016T142705, end_date=20251016T142705
[2025-10-16T14:27:05.326+0000] {standard_task_runner.py:109} ERROR - Failed to execute job 6 for task soda_scan (Bash command failed. The command returned a non-zero exit code 127.; 89)
[2025-10-16T14:27:05.352+0000] {local_task_job_runner.py:225} INFO - Task exited with return code 1
[2025-10-16T14:27:05.370+0000] {taskinstance.py:2651} INFO - 0 downstream tasks scheduled from follow-on schedule check
[2025-10-16T14:34:53.855+0000] {taskinstance.py:1103} INFO - Dependencies all met for dep_context=non-requeueable deps ti=<TaskInstance: csv_etl_pipeline.soda_scan scheduled__2025-10-15T20:00:00+00:00 [queued]>
[2025-10-16T14:34:53.868+0000] {taskinstance.py:1103} INFO - Dependencies all met for dep_context=requeueable deps ti=<TaskInstance: csv_etl_pipeline.soda_scan scheduled__2025-10-15T20:00:00+00:00 [queued]>
[2025-10-16T14:34:53.869+0000] {taskinstance.py:1308} INFO - Starting attempt 1 of 1
[2025-10-16T14:34:53.885+0000] {taskinstance.py:1327} INFO - Executing <Task(BashOperator): soda_scan> on 2025-10-15 20:00:00+00:00
[2025-10-16T14:34:53.897+0000] {standard_task_runner.py:57} INFO - Started process 98 to run task
[2025-10-16T14:34:53.905+0000] {standard_task_runner.py:84} INFO - Running: ['***', 'tasks', 'run', 'csv_etl_pipeline', 'soda_scan', 'scheduled__2025-10-15T20:00:00+00:00', '--job-id', '6', '--raw', '--subdir', 'DAGS_FOLDER/etl.py', '--cfg-path', '/tmp/tmp9rth31t8']
[2025-10-16T14:34:53.906+0000] {standard_task_runner.py:85} INFO - Job 6: Subtask soda_scan
[2025-10-16T14:34:53.997+0000] {task_command.py:410} INFO - Running <TaskInstance: csv_etl_pipeline.soda_scan scheduled__2025-10-15T20:00:00+00:00 [running]> on host 44e366da6235
[2025-10-16T14:34:54.101+0000] {taskinstance.py:1547} INFO - Exporting env vars: AIRFLOW_CTX_DAG_OWNER='***' AIRFLOW_CTX_DAG_ID='csv_etl_pipeline' AIRFLOW_CTX_TASK_ID='soda_scan' AIRFLOW_CTX_EXECUTION_DATE='2025-10-15T20:00:00+00:00' AIRFLOW_CTX_TRY_NUMBER='1' AIRFLOW_CTX_DAG_RUN_ID='scheduled__2025-10-15T20:00:00+00:00'
[2025-10-16T14:34:54.105+0000] {subprocess.py:63} INFO - Tmp dir root location: 
 /tmp
[2025-10-16T14:34:54.106+0000] {subprocess.py:75} INFO - Running command: ['/bin/bash', '-c', 'soda scan -d ***_pg -c /opt/***/dags/soda/configuration.yml /opt/***/dags/soda/checks.yml']
[2025-10-16T14:34:54.123+0000] {subprocess.py:86} INFO - Output:
[2025-10-16T14:34:54.128+0000] {subprocess.py:93} INFO - /bin/bash: line 1: soda: command not found
[2025-10-16T14:34:54.129+0000] {subprocess.py:97} INFO - Command exited with return code 127
[2025-10-16T14:34:54.141+0000] {taskinstance.py:1824} ERROR - Task failed with exception
Traceback (most recent call last):
  File "/home/airflow/.local/lib/python3.7/site-packages/airflow/operators/bash.py", line 211, in execute
    f"Bash command failed. The command returned a non-zero exit code {result.exit_code}."
airflow.exceptions.AirflowException: Bash command failed. The command returned a non-zero exit code 127.
[2025-10-16T14:34:54.145+0000] {taskinstance.py:1350} INFO - Marking task as FAILED. dag_id=csv_etl_pipeline, task_id=soda_scan, execution_date=20251015T200000, start_date=20251016T143453, end_date=20251016T143454
[2025-10-16T14:34:54.162+0000] {standard_task_runner.py:109} ERROR - Failed to execute job 6 for task soda_scan (Bash command failed. The command returned a non-zero exit code 127.; 98)
[2025-10-16T14:34:54.198+0000] {local_task_job_runner.py:225} INFO - Task exited with return code 1
[2025-10-16T14:34:54.221+0000] {taskinstance.py:2651} INFO - 0 downstream tasks scheduled from follow-on schedule check
[2025-10-16T15:10:49.660+0000] {taskinstance.py:1159} INFO - Dependencies all met for dep_context=non-requeueable deps ti=<TaskInstance: csv_etl_pipeline.soda_scan scheduled__2025-10-15T20:00:00+00:00 [queued]>
[2025-10-16T15:10:49.673+0000] {taskinstance.py:1159} INFO - Dependencies all met for dep_context=requeueable deps ti=<TaskInstance: csv_etl_pipeline.soda_scan scheduled__2025-10-15T20:00:00+00:00 [queued]>
[2025-10-16T15:10:49.673+0000] {taskinstance.py:1361} INFO - Starting attempt 1 of 1
[2025-10-16T15:10:49.691+0000] {taskinstance.py:1382} INFO - Executing <Task(BashOperator): soda_scan> on 2025-10-15 20:00:00+00:00
[2025-10-16T15:10:49.701+0000] {standard_task_runner.py:57} INFO - Started process 83 to run task
[2025-10-16T15:10:49.705+0000] {standard_task_runner.py:84} INFO - Running: ['***', 'tasks', 'run', 'csv_etl_pipeline', 'soda_scan', 'scheduled__2025-10-15T20:00:00+00:00', '--job-id', '6', '--raw', '--subdir', 'DAGS_FOLDER/etl.py', '--cfg-path', '/tmp/tmp9q4bcxbm']
[2025-10-16T15:10:49.707+0000] {standard_task_runner.py:85} INFO - Job 6: Subtask soda_scan
[2025-10-16T15:10:49.773+0000] {task_command.py:416} INFO - Running <TaskInstance: csv_etl_pipeline.soda_scan scheduled__2025-10-15T20:00:00+00:00 [running]> on host 9632773e4775
[2025-10-16T15:10:49.881+0000] {taskinstance.py:1662} INFO - Exporting env vars: AIRFLOW_CTX_DAG_OWNER='***' AIRFLOW_CTX_DAG_ID='csv_etl_pipeline' AIRFLOW_CTX_TASK_ID='soda_scan' AIRFLOW_CTX_EXECUTION_DATE='2025-10-15T20:00:00+00:00' AIRFLOW_CTX_TRY_NUMBER='1' AIRFLOW_CTX_DAG_RUN_ID='scheduled__2025-10-15T20:00:00+00:00'
[2025-10-16T15:10:49.886+0000] {subprocess.py:63} INFO - Tmp dir root location: /tmp
[2025-10-16T15:10:49.887+0000] {subprocess.py:75} INFO - Running command: ['/bin/bash', '-c', 'soda scan -d ***_pg -c /opt/***/dags/soda/configuration.yml /opt/***/dags/soda/checks.yml']
[2025-10-16T15:10:49.905+0000] {subprocess.py:86} INFO - Output:
[2025-10-16T15:10:51.064+0000] {subprocess.py:93} INFO - [15:10:51] Soda Core 3.5.6
[2025-10-16T15:10:51.065+0000] {subprocess.py:93} INFO - [15:10:51] Configuration path '/opt/***/dags/soda/configuration.yml' does not exist
[2025-10-16T15:10:51.066+0000] {subprocess.py:93} INFO - [15:10:51] Path "/opt/***/dags/soda/checks.yml" does not exist
[2025-10-16T15:10:51.069+0000] {subprocess.py:93} INFO - [15:10:51] Scan summary:
[2025-10-16T15:10:51.069+0000] {subprocess.py:93} INFO - [15:10:51] No valid checks found, 0 checks evaluated.
[2025-10-16T15:10:51.069+0000] {subprocess.py:93} INFO - [15:10:51] 2 errors.
[2025-10-16T15:10:51.069+0000] {subprocess.py:93} INFO - [15:10:51] Oops! 2 errors. 0 failures. 0 warnings. 0 pass.
[2025-10-16T15:10:51.069+0000] {subprocess.py:93} INFO - ERRORS:
[2025-10-16T15:10:51.069+0000] {subprocess.py:93} INFO - [15:10:51] Configuration path '/opt/***/dags/soda/configuration.yml' does not exist
[2025-10-16T15:10:51.070+0000] {subprocess.py:93} INFO - [15:10:51] Path "/opt/***/dags/soda/checks.yml" does not exist
[2025-10-16T15:10:51.307+0000] {subprocess.py:97} INFO - Command exited with return code 3
[2025-10-16T15:10:51.316+0000] {taskinstance.py:1937} ERROR - Task failed with exception
Traceback (most recent call last):
  File "/home/airflow/.local/lib/python3.8/site-packages/airflow/operators/bash.py", line 210, in execute
    raise AirflowException(
airflow.exceptions.AirflowException: Bash command failed. The command returned a non-zero exit code 3.
[2025-10-16T15:10:51.319+0000] {taskinstance.py:1400} INFO - Marking task as FAILED. dag_id=csv_etl_pipeline, task_id=soda_scan, execution_date=20251015T200000, start_date=20251016T151049, end_date=20251016T151051
[2025-10-16T15:10:51.329+0000] {standard_task_runner.py:104} ERROR - Failed to execute job 6 for task soda_scan (Bash command failed. The command returned a non-zero exit code 3.; 83)
[2025-10-16T15:10:51.363+0000] {local_task_job_runner.py:228} INFO - Task exited with return code 1
[2025-10-16T15:10:51.382+0000] {taskinstance.py:2778} INFO - 0 downstream tasks scheduled from follow-on schedule check
[2025-10-16T15:14:20.810+0000] {taskinstance.py:1159} INFO - Dependencies all met for dep_context=non-requeueable deps ti=<TaskInstance: csv_etl_pipeline.soda_scan scheduled__2025-10-15T20:00:00+00:00 [queued]>
[2025-10-16T15:14:20.817+0000] {taskinstance.py:1159} INFO - Dependencies all met for dep_context=requeueable deps ti=<TaskInstance: csv_etl_pipeline.soda_scan scheduled__2025-10-15T20:00:00+00:00 [queued]>
[2025-10-16T15:14:20.817+0000] {taskinstance.py:1361} INFO - Starting attempt 1 of 1
[2025-10-16T15:14:20.826+0000] {taskinstance.py:1382} INFO - Executing <Task(BashOperator): soda_scan> on 2025-10-15 20:00:00+00:00
[2025-10-16T15:14:20.831+0000] {standard_task_runner.py:57} INFO - Started process 84 to run task
[2025-10-16T15:14:20.835+0000] {standard_task_runner.py:84} INFO - Running: ['***', 'tasks', 'run', 'csv_etl_pipeline', 'soda_scan', 'scheduled__2025-10-15T20:00:00+00:00', '--job-id', '6', '--raw', '--subdir', 'DAGS_FOLDER/etl.py', '--cfg-path', '/tmp/tmpmxpb3ypq']
[2025-10-16T15:14:20.836+0000] {standard_task_runner.py:85} INFO - Job 6: Subtask soda_scan
[2025-10-16T15:14:20.884+0000] {task_command.py:416} INFO - Running <TaskInstance: csv_etl_pipeline.soda_scan scheduled__2025-10-15T20:00:00+00:00 [running]> on host db55547a7972
[2025-10-16T15:14:20.945+0000] {taskinstance.py:1662} INFO - Exporting env vars: AIRFLOW_CTX_DAG_OWNER='***' AIRFLOW_CTX_DAG_ID='csv_etl_pipeline' AIRFLOW_CTX_TASK_ID='soda_scan' AIRFLOW_CTX_EXECUTION_DATE='2025-10-15T20:00:00+00:00' AIRFLOW_CTX_TRY_NUMBER='1' AIRFLOW_CTX_DAG_RUN_ID='scheduled__2025-10-15T20:00:00+00:00'
[2025-10-16T15:14:20.948+0000] {subprocess.py:63} INFO - Tmp dir root location: /tmp
[2025-10-16T15:14:20.948+0000] {subprocess.py:75} INFO - Running command: ['/bin/bash', '-c', 'soda scan -d ***_pg -c /opt/***/dags/soda/configuration.yml /opt/***/dags/soda/checks.yml']
[2025-10-16T15:14:20.959+0000] {subprocess.py:86} INFO - Output:
[2025-10-16T15:14:21.802+0000] {subprocess.py:93} INFO - [15:14:21] Soda Core 3.5.6
[2025-10-16T15:14:21.883+0000] {subprocess.py:93} INFO - [15:14:21] Counting invalid without valid or invalid specification does not make sense. ("invalid_count(price) = 0" @ line=9,col=5 in /opt/***/dags/soda/checks.yml)
[2025-10-16T15:14:21.885+0000] {subprocess.py:93} INFO - [15:14:21] Scan summary:
[2025-10-16T15:14:21.885+0000] {subprocess.py:93} INFO - [15:14:21] 5/6 checks PASSED:
[2025-10-16T15:14:21.886+0000] {subprocess.py:93} INFO - [15:14:21]     games in ***_pg
[2025-10-16T15:14:21.886+0000] {subprocess.py:93} INFO - [15:14:21]       row_count > 0 [PASSED]
[2025-10-16T15:14:21.886+0000] {subprocess.py:93} INFO - [15:14:21]       missing_count(game) = 0 [PASSED]
[2025-10-16T15:14:21.886+0000] {subprocess.py:93} INFO - [15:14:21]       duplicate_count(urlgame) = 0 [PASSED]
[2025-10-16T15:14:21.886+0000] {subprocess.py:93} INFO - [15:14:21]     prices in ***_pg
[2025-10-16T15:14:21.886+0000] {subprocess.py:93} INFO - [15:14:21]       missing_count(price) = 0 [PASSED]
[2025-10-16T15:14:21.886+0000] {subprocess.py:93} INFO - [15:14:21]       invalid_count(price) = 0 [PASSED]
[2025-10-16T15:14:21.886+0000] {subprocess.py:93} INFO - [15:14:21] 1/6 checks FAILED:
[2025-10-16T15:14:21.886+0000] {subprocess.py:93} INFO - [15:14:21]     prices in ***_pg
[2025-10-16T15:14:21.886+0000] {subprocess.py:93} INFO - [15:14:21]       row_count > 0 [FAILED]
[2025-10-16T15:14:21.886+0000] {subprocess.py:93} INFO - [15:14:21]         check_value: 0
[2025-10-16T15:14:21.886+0000] {subprocess.py:93} INFO - [15:14:21] Oops! 1 failures. 0 warnings. 0 errors. 5 pass.
[2025-10-16T15:14:22.102+0000] {subprocess.py:97} INFO - Command exited with return code 2
[2025-10-16T15:14:22.112+0000] {taskinstance.py:1937} ERROR - Task failed with exception
Traceback (most recent call last):
  File "/home/airflow/.local/lib/python3.8/site-packages/airflow/operators/bash.py", line 210, in execute
    raise AirflowException(
airflow.exceptions.AirflowException: Bash command failed. The command returned a non-zero exit code 2.
[2025-10-16T15:14:22.115+0000] {taskinstance.py:1400} INFO - Marking task as FAILED. dag_id=csv_etl_pipeline, task_id=soda_scan, execution_date=20251015T200000, start_date=20251016T151420, end_date=20251016T151422
[2025-10-16T15:14:22.126+0000] {standard_task_runner.py:104} ERROR - Failed to execute job 6 for task soda_scan (Bash command failed. The command returned a non-zero exit code 2.; 84)
[2025-10-16T15:14:22.173+0000] {local_task_job_runner.py:228} INFO - Task exited with return code 1
[2025-10-16T15:14:22.193+0000] {taskinstance.py:2778} INFO - 0 downstream tasks scheduled from follow-on schedule check
[2025-10-16T15:17:55.426+0000] {taskinstance.py:1159} INFO - Dependencies all met for dep_context=non-requeueable deps ti=<TaskInstance: csv_etl_pipeline.soda_scan scheduled__2025-10-15T20:00:00+00:00 [queued]>
[2025-10-16T15:17:55.434+0000] {taskinstance.py:1159} INFO - Dependencies all met for dep_context=requeueable deps ti=<TaskInstance: csv_etl_pipeline.soda_scan scheduled__2025-10-15T20:00:00+00:00 [queued]>
[2025-10-16T15:17:55.435+0000] {taskinstance.py:1361} INFO - Starting attempt 1 of 1
[2025-10-16T15:17:55.447+0000] {taskinstance.py:1382} INFO - Executing <Task(BashOperator): soda_scan> on 2025-10-15 20:00:00+00:00
[2025-10-16T15:17:55.453+0000] {standard_task_runner.py:57} INFO - Started process 83 to run task
[2025-10-16T15:17:55.457+0000] {standard_task_runner.py:84} INFO - Running: ['***', 'tasks', 'run', 'csv_etl_pipeline', 'soda_scan', 'scheduled__2025-10-15T20:00:00+00:00', '--job-id', '6', '--raw', '--subdir', 'DAGS_FOLDER/etl.py', '--cfg-path', '/tmp/tmpwlw_m4fo']
[2025-10-16T15:17:55.458+0000] {standard_task_runner.py:85} INFO - Job 6: Subtask soda_scan
[2025-10-16T15:17:55.501+0000] {task_command.py:416} INFO - Running <TaskInstance: csv_etl_pipeline.soda_scan scheduled__2025-10-15T20:00:00+00:00 [running]> on host b4e3001b90ac
[2025-10-16T15:17:55.562+0000] {taskinstance.py:1662} INFO - Exporting env vars: AIRFLOW_CTX_DAG_OWNER='***' AIRFLOW_CTX_DAG_ID='csv_etl_pipeline' AIRFLOW_CTX_TASK_ID='soda_scan' AIRFLOW_CTX_EXECUTION_DATE='2025-10-15T20:00:00+00:00' AIRFLOW_CTX_TRY_NUMBER='1' AIRFLOW_CTX_DAG_RUN_ID='scheduled__2025-10-15T20:00:00+00:00'
[2025-10-16T15:17:55.565+0000] {subprocess.py:63} INFO - Tmp dir root location: /tmp
[2025-10-16T15:17:55.566+0000] {subprocess.py:75} INFO - Running command: ['/bin/bash', '-c', 'soda scan -d ***_pg -c /opt/***/dags/soda/configuration.yml /opt/***/dags/soda/checks.yml']
[2025-10-16T15:17:55.578+0000] {subprocess.py:86} INFO - Output:
[2025-10-16T15:17:56.526+0000] {subprocess.py:93} INFO - [15:17:56] Soda Core 3.5.6
[2025-10-16T15:17:56.595+0000] {subprocess.py:93} INFO - [15:17:56] Counting invalid without valid or invalid specification does not make sense. ("invalid_count(price) = 0" @ line=9,col=5 in /opt/***/dags/soda/checks.yml)
[2025-10-16T15:17:56.597+0000] {subprocess.py:93} INFO - [15:17:56] Scan summary:
[2025-10-16T15:17:56.597+0000] {subprocess.py:93} INFO - [15:17:56] 6/6 checks PASSED:
[2025-10-16T15:17:56.597+0000] {subprocess.py:93} INFO - [15:17:56]     games in ***_pg
[2025-10-16T15:17:56.597+0000] {subprocess.py:93} INFO - [15:17:56]       row_count > 0 [PASSED]
[2025-10-16T15:17:56.597+0000] {subprocess.py:93} INFO - [15:17:56]       missing_count(game) = 0 [PASSED]
[2025-10-16T15:17:56.597+0000] {subprocess.py:93} INFO - [15:17:56]       duplicate_count(urlgame) = 0 [PASSED]
[2025-10-16T15:17:56.597+0000] {subprocess.py:93} INFO - [15:17:56]     prices in ***_pg
[2025-10-16T15:17:56.597+0000] {subprocess.py:93} INFO - [15:17:56]       row_count = 0 [PASSED]
[2025-10-16T15:17:56.597+0000] {subprocess.py:93} INFO - [15:17:56]       missing_count(price) = 0 [PASSED]
[2025-10-16T15:17:56.598+0000] {subprocess.py:93} INFO - [15:17:56]       invalid_count(price) = 0 [PASSED]
[2025-10-16T15:17:56.598+0000] {subprocess.py:93} INFO - [15:17:56] All is good. No failures. No warnings. No errors.
[2025-10-16T15:17:56.816+0000] {subprocess.py:97} INFO - Command exited with return code 0
[2025-10-16T15:17:56.845+0000] {taskinstance.py:1400} INFO - Marking task as SUCCESS. dag_id=csv_etl_pipeline, task_id=soda_scan, execution_date=20251015T200000, start_date=20251016T151755, end_date=20251016T151756
[2025-10-16T15:17:56.873+0000] {local_task_job_runner.py:228} INFO - Task exited with return code 0
[2025-10-16T15:17:56.890+0000] {taskinstance.py:2778} INFO - 1 downstream tasks scheduled from follow-on schedule check
