[2025-10-16T13:01:02.495+0000] {taskinstance.py:1103} INFO - Dependencies all met for dep_context=non-requeueable deps ti=<TaskInstance: csv_etl_pipeline.request_api scheduled__2025-10-16T13:00:00+00:00 [queued]>
[2025-10-16T13:01:02.502+0000] {taskinstance.py:1103} INFO - Dependencies all met for dep_context=requeueable deps ti=<TaskInstance: csv_etl_pipeline.request_api scheduled__2025-10-16T13:00:00+00:00 [queued]>
[2025-10-16T13:01:02.503+0000] {taskinstance.py:1308} INFO - Starting attempt 1 of 1
[2025-10-16T13:01:02.514+0000] {taskinstance.py:1327} INFO - Executing <Task(PythonOperator): request_api> on 2025-10-16 13:00:00+00:00
[2025-10-16T13:01:02.521+0000] {standard_task_runner.py:57} INFO - Started process 98 to run task
[2025-10-16T13:01:02.524+0000] {standard_task_runner.py:84} INFO - Running: ['***', 'tasks', 'run', 'csv_etl_pipeline', 'request_api', 'scheduled__2025-10-16T13:00:00+00:00', '--job-id', '6', '--raw', '--subdir', 'DAGS_FOLDER/etl.py', '--cfg-path', '/tmp/tmpbokf_p4o']
[2025-10-16T13:01:02.525+0000] {standard_task_runner.py:85} INFO - Job 6: Subtask request_api
[2025-10-16T13:01:02.571+0000] {task_command.py:410} INFO - Running <TaskInstance: csv_etl_pipeline.request_api scheduled__2025-10-16T13:00:00+00:00 [running]> on host f445feefde9d
[2025-10-16T13:01:02.636+0000] {taskinstance.py:1547} INFO - Exporting env vars: AIRFLOW_CTX_DAG_OWNER='***' AIRFLOW_CTX_DAG_ID='csv_etl_pipeline' AIRFLOW_CTX_TASK_ID='request_api' AIRFLOW_CTX_EXECUTION_DATE='2025-10-16T13:00:00+00:00' AIRFLOW_CTX_TRY_NUMBER='1' AIRFLOW_CTX_DAG_RUN_ID='scheduled__2025-10-16T13:00:00+00:00'
[2025-10-16T13:01:02.647+0000] {taskinstance.py:1824} ERROR - Task failed with exception
Traceback (most recent call last):
  File "/home/airflow/.local/lib/python3.7/site-packages/airflow/operators/python.py", line 181, in execute
    return_value = self.execute_callable()
  File "/home/airflow/.local/lib/python3.7/site-packages/airflow/operators/python.py", line 198, in execute_callable
    return self.python_callable(*self.op_args, **self.op_kwargs)
  File "/opt/airflow/dags/etl.py", line 117, in request_api
    df = pd.read_json(data)
  File "/home/airflow/.local/lib/python3.7/site-packages/pandas/util/_decorators.py", line 207, in wrapper
    return func(*args, **kwargs)
  File "/home/airflow/.local/lib/python3.7/site-packages/pandas/util/_decorators.py", line 311, in wrapper
    return func(*args, **kwargs)
  File "/home/airflow/.local/lib/python3.7/site-packages/pandas/io/json/_json.py", line 607, in read_json
    encoding_errors=encoding_errors,
  File "/home/airflow/.local/lib/python3.7/site-packages/pandas/io/json/_json.py", line 675, in __init__
    data = self._get_data_from_filepath(filepath_or_buffer)
  File "/home/airflow/.local/lib/python3.7/site-packages/pandas/io/json/_json.py", line 718, in _get_data_from_filepath
    errors=self.encoding_errors,
  File "/home/airflow/.local/lib/python3.7/site-packages/pandas/io/common.py", line 614, in get_handle
    storage_options=storage_options,
  File "/home/airflow/.local/lib/python3.7/site-packages/pandas/io/common.py", line 396, in _get_filepath_or_buffer
    raise ValueError(msg)
ValueError: Invalid file path or buffer object type: <class 'NoneType'>
[2025-10-16T13:01:02.656+0000] {taskinstance.py:1350} INFO - Marking task as FAILED. dag_id=csv_etl_pipeline, task_id=request_api, execution_date=20251016T130000, start_date=20251016T130102, end_date=20251016T130102
[2025-10-16T13:01:02.665+0000] {standard_task_runner.py:109} ERROR - Failed to execute job 6 for task request_api (Invalid file path or buffer object type: <class 'NoneType'>; 98)
[2025-10-16T13:01:02.695+0000] {local_task_job_runner.py:225} INFO - Task exited with return code 1
[2025-10-16T13:01:02.719+0000] {taskinstance.py:2651} INFO - 0 downstream tasks scheduled from follow-on schedule check
