[2025-10-16T13:08:03.792+0000] {taskinstance.py:1103} INFO - Dependencies all met for dep_context=non-requeueable deps ti=<TaskInstance: csv_etl_pipeline.request_api scheduled__2025-10-16T13:07:00+00:00 [queued]>
[2025-10-16T13:08:03.800+0000] {taskinstance.py:1103} INFO - Dependencies all met for dep_context=requeueable deps ti=<TaskInstance: csv_etl_pipeline.request_api scheduled__2025-10-16T13:07:00+00:00 [queued]>
[2025-10-16T13:08:03.800+0000] {taskinstance.py:1308} INFO - Starting attempt 1 of 1
[2025-10-16T13:08:03.813+0000] {taskinstance.py:1327} INFO - Executing <Task(PythonOperator): request_api> on 2025-10-16 13:07:00+00:00
[2025-10-16T13:08:03.819+0000] {standard_task_runner.py:57} INFO - Started process 136 to run task
[2025-10-16T13:08:03.824+0000] {standard_task_runner.py:84} INFO - Running: ['***', 'tasks', 'run', 'csv_etl_pipeline', 'request_api', 'scheduled__2025-10-16T13:07:00+00:00', '--job-id', '12', '--raw', '--subdir', 'DAGS_FOLDER/etl.py', '--cfg-path', '/tmp/tmp7bq_z9hl']
[2025-10-16T13:08:03.824+0000] {standard_task_runner.py:85} INFO - Job 12: Subtask request_api
[2025-10-16T13:08:03.870+0000] {task_command.py:410} INFO - Running <TaskInstance: csv_etl_pipeline.request_api scheduled__2025-10-16T13:07:00+00:00 [running]> on host 2453e4d8fab4
[2025-10-16T13:08:03.941+0000] {taskinstance.py:1547} INFO - Exporting env vars: AIRFLOW_CTX_DAG_OWNER='***' AIRFLOW_CTX_DAG_ID='csv_etl_pipeline' AIRFLOW_CTX_TASK_ID='request_api' AIRFLOW_CTX_EXECUTION_DATE='2025-10-16T13:07:00+00:00' AIRFLOW_CTX_TRY_NUMBER='1' AIRFLOW_CTX_DAG_RUN_ID='scheduled__2025-10-16T13:07:00+00:00'
[2025-10-16T13:08:03.955+0000] {logging_mixin.py:149} INFO - None
[2025-10-16T13:08:03.955+0000] {taskinstance.py:1824} ERROR - Task failed with exception
Traceback (most recent call last):
  File "/home/airflow/.local/lib/python3.7/site-packages/airflow/operators/python.py", line 181, in execute
    return_value = self.execute_callable()
  File "/home/airflow/.local/lib/python3.7/site-packages/airflow/operators/python.py", line 198, in execute_callable
    return self.python_callable(*self.op_args, **self.op_kwargs)
  File "/opt/airflow/dags/etl.py", line 118, in request_api
    df = pd.read_json(StringIO(data))
NameError: name 'StringIO' is not defined
[2025-10-16T13:08:03.963+0000] {taskinstance.py:1350} INFO - Marking task as FAILED. dag_id=csv_etl_pipeline, task_id=request_api, execution_date=20251016T130700, start_date=20251016T130803, end_date=20251016T130803
[2025-10-16T13:08:03.974+0000] {standard_task_runner.py:109} ERROR - Failed to execute job 12 for task request_api (name 'StringIO' is not defined; 136)
[2025-10-16T13:08:03.994+0000] {local_task_job_runner.py:225} INFO - Task exited with return code 1
[2025-10-16T13:08:04.022+0000] {taskinstance.py:2651} INFO - 0 downstream tasks scheduled from follow-on schedule check
