[2025-10-16T13:24:10.669+0000] {taskinstance.py:1103} INFO - Dependencies all met for dep_context=non-requeueable deps ti=<TaskInstance: csv_etl_pipeline.request_api scheduled__2025-10-16T13:23:00+00:00 [queued]>
[2025-10-16T13:24:10.676+0000] {taskinstance.py:1103} INFO - Dependencies all met for dep_context=requeueable deps ti=<TaskInstance: csv_etl_pipeline.request_api scheduled__2025-10-16T13:23:00+00:00 [queued]>
[2025-10-16T13:24:10.676+0000] {taskinstance.py:1308} INFO - Starting attempt 1 of 1
[2025-10-16T13:24:10.688+0000] {taskinstance.py:1327} INFO - Executing <Task(PythonOperator): request_api> on 2025-10-16 13:23:00+00:00
[2025-10-16T13:24:10.694+0000] {standard_task_runner.py:57} INFO - Started process 166 to run task
[2025-10-16T13:24:10.698+0000] {standard_task_runner.py:84} INFO - Running: ['***', 'tasks', 'run', 'csv_etl_pipeline', 'request_api', 'scheduled__2025-10-16T13:23:00+00:00', '--job-id', '20', '--raw', '--subdir', 'DAGS_FOLDER/etl.py', '--cfg-path', '/tmp/tmphvn0_e91']
[2025-10-16T13:24:10.699+0000] {standard_task_runner.py:85} INFO - Job 20: Subtask request_api
[2025-10-16T13:24:10.748+0000] {task_command.py:410} INFO - Running <TaskInstance: csv_etl_pipeline.request_api scheduled__2025-10-16T13:23:00+00:00 [running]> on host 252b671eecea
[2025-10-16T13:24:10.832+0000] {taskinstance.py:1547} INFO - Exporting env vars: AIRFLOW_CTX_DAG_OWNER='***' AIRFLOW_CTX_DAG_ID='csv_etl_pipeline' AIRFLOW_CTX_TASK_ID='request_api' AIRFLOW_CTX_EXECUTION_DATE='2025-10-16T13:23:00+00:00' AIRFLOW_CTX_TRY_NUMBER='1' AIRFLOW_CTX_DAG_RUN_ID='scheduled__2025-10-16T13:23:00+00:00'
[2025-10-16T13:24:10.846+0000] {logging_mixin.py:149} INFO - {"id":{"0":1},"urlgame":{"0":"https:\/\/www.instant-gaming.com\/en\/8003-buy-celeste-pc-mac-game-steam\/"},"game":{"0":"Celeste"}}
[2025-10-16T13:24:11.305+0000] {taskinstance.py:1824} ERROR - Task failed with exception
Traceback (most recent call last):
  File "/home/airflow/.local/lib/python3.7/site-packages/airflow/operators/python.py", line 181, in execute
    return_value = self.execute_callable()
  File "/home/airflow/.local/lib/python3.7/site-packages/airflow/operators/python.py", line 198, in execute_callable
    return self.python_callable(*self.op_args, **self.op_kwargs)
  File "/opt/airflow/dags/etl.py", line 158, in request_api
    f["logdate"] = datetime.now().isoformat()
NameError: name 'f' is not defined
[2025-10-16T13:24:11.314+0000] {taskinstance.py:1350} INFO - Marking task as FAILED. dag_id=csv_etl_pipeline, task_id=request_api, execution_date=20251016T132300, start_date=20251016T132410, end_date=20251016T132411
[2025-10-16T13:24:11.325+0000] {standard_task_runner.py:109} ERROR - Failed to execute job 20 for task request_api (name 'f' is not defined; 166)
[2025-10-16T13:24:11.351+0000] {local_task_job_runner.py:225} INFO - Task exited with return code 1
[2025-10-16T13:24:11.373+0000] {taskinstance.py:2651} INFO - 0 downstream tasks scheduled from follow-on schedule check
