[2025-10-16T13:15:33.034+0000] {taskinstance.py:1103} INFO - Dependencies all met for dep_context=non-requeueable deps ti=<TaskInstance: csv_etl_pipeline.load_data manual__2025-10-16T13:15:25.712314+00:00 [queued]>
[2025-10-16T13:15:33.043+0000] {taskinstance.py:1103} INFO - Dependencies all met for dep_context=requeueable deps ti=<TaskInstance: csv_etl_pipeline.load_data manual__2025-10-16T13:15:25.712314+00:00 [queued]>
[2025-10-16T13:15:33.043+0000] {taskinstance.py:1308} INFO - Starting attempt 1 of 1
[2025-10-16T13:15:33.059+0000] {taskinstance.py:1327} INFO - Executing <Task(PythonOperator): load_data> on 2025-10-16 13:15:25.712314+00:00
[2025-10-16T13:15:33.066+0000] {standard_task_runner.py:57} INFO - Started process 132 to run task
[2025-10-16T13:15:33.072+0000] {standard_task_runner.py:84} INFO - Running: ['***', 'tasks', 'run', 'csv_etl_pipeline', 'load_data', 'manual__2025-10-16T13:15:25.712314+00:00', '--job-id', '14', '--raw', '--subdir', 'DAGS_FOLDER/etl.py', '--cfg-path', '/tmp/tmp32a0ea5t']
[2025-10-16T13:15:33.072+0000] {standard_task_runner.py:85} INFO - Job 14: Subtask load_data
[2025-10-16T13:15:33.133+0000] {task_command.py:410} INFO - Running <TaskInstance: csv_etl_pipeline.load_data manual__2025-10-16T13:15:25.712314+00:00 [running]> on host 67bb395cac75
[2025-10-16T13:15:33.239+0000] {taskinstance.py:1547} INFO - Exporting env vars: AIRFLOW_CTX_DAG_OWNER='***' AIRFLOW_CTX_DAG_ID='csv_etl_pipeline' AIRFLOW_CTX_TASK_ID='load_data' AIRFLOW_CTX_EXECUTION_DATE='2025-10-16T13:15:25.712314+00:00' AIRFLOW_CTX_TRY_NUMBER='1' AIRFLOW_CTX_DAG_RUN_ID='manual__2025-10-16T13:15:25.712314+00:00'
[2025-10-16T13:15:33.272+0000] {taskinstance.py:1824} ERROR - Task failed with exception
Traceback (most recent call last):
  File "/home/airflow/.local/lib/python3.7/site-packages/airflow/operators/python.py", line 181, in execute
    return_value = self.execute_callable()
  File "/home/airflow/.local/lib/python3.7/site-packages/airflow/operators/python.py", line 198, in execute_callable
    return self.python_callable(*self.op_args, **self.op_kwargs)
  File "/opt/airflow/dags/etl.py", line 187, in load_data
    load_to_db(df)
  File "/opt/airflow/dags/etl.py", line 101, in load_to_db
    row['logdate']
psycopg2.errors.DatatypeMismatch: column "dateprice" is of type timestamp without time zone but expression is of type numeric
LINE 3:             VALUES (1.0, 6.65, 1760620530059.0)
                                       ^
HINT:  You will need to rewrite or cast the expression.

[2025-10-16T13:15:33.282+0000] {taskinstance.py:1350} INFO - Marking task as FAILED. dag_id=csv_etl_pipeline, task_id=load_data, execution_date=20251016T131525, start_date=20251016T131533, end_date=20251016T131533
[2025-10-16T13:15:33.295+0000] {standard_task_runner.py:109} ERROR - Failed to execute job 14 for task load_data (column "dateprice" is of type timestamp without time zone but expression is of type numeric
LINE 3:             VALUES (1.0, 6.65, 1760620530059.0)
                                       ^
HINT:  You will need to rewrite or cast the expression.
; 132)
[2025-10-16T13:15:33.323+0000] {local_task_job_runner.py:225} INFO - Task exited with return code 1
[2025-10-16T13:15:33.340+0000] {taskinstance.py:2651} INFO - 0 downstream tasks scheduled from follow-on schedule check
