[2025-10-16T13:19:56.534+0000] {taskinstance.py:1103} INFO - Dependencies all met for dep_context=non-requeueable deps ti=<TaskInstance: csv_etl_pipeline.request_api scheduled__2025-10-16T13:18:00+00:00 [queued]>
[2025-10-16T13:19:56.544+0000] {taskinstance.py:1103} INFO - Dependencies all met for dep_context=requeueable deps ti=<TaskInstance: csv_etl_pipeline.request_api scheduled__2025-10-16T13:18:00+00:00 [queued]>
[2025-10-16T13:19:56.544+0000] {taskinstance.py:1308} INFO - Starting attempt 1 of 1
[2025-10-16T13:19:56.559+0000] {taskinstance.py:1327} INFO - Executing <Task(PythonOperator): request_api> on 2025-10-16 13:18:00+00:00
[2025-10-16T13:19:56.566+0000] {standard_task_runner.py:57} INFO - Started process 83 to run task
[2025-10-16T13:19:56.570+0000] {standard_task_runner.py:84} INFO - Running: ['***', 'tasks', 'run', 'csv_etl_pipeline', 'request_api', 'scheduled__2025-10-16T13:18:00+00:00', '--job-id', '4', '--raw', '--subdir', 'DAGS_FOLDER/etl.py', '--cfg-path', '/tmp/tmpx_8uts70']
[2025-10-16T13:19:56.571+0000] {standard_task_runner.py:85} INFO - Job 4: Subtask request_api
[2025-10-16T13:19:56.630+0000] {task_command.py:410} INFO - Running <TaskInstance: csv_etl_pipeline.request_api scheduled__2025-10-16T13:18:00+00:00 [running]> on host c0ea71ebe8b0
[2025-10-16T13:19:56.712+0000] {taskinstance.py:1547} INFO - Exporting env vars: AIRFLOW_CTX_DAG_OWNER='***' AIRFLOW_CTX_DAG_ID='csv_etl_pipeline' AIRFLOW_CTX_TASK_ID='request_api' AIRFLOW_CTX_EXECUTION_DATE='2025-10-16T13:18:00+00:00' AIRFLOW_CTX_TRY_NUMBER='1' AIRFLOW_CTX_DAG_RUN_ID='scheduled__2025-10-16T13:18:00+00:00'
[2025-10-16T13:19:56.724+0000] {logging_mixin.py:149} INFO - {"id":{"0":1},"urlgame":{"0":"https:\/\/www.instant-gaming.com\/en\/8003-buy-celeste-pc-mac-game-steam\/"},"game":{"0":"Celeste"}}
[2025-10-16T13:19:57.351+0000] {taskinstance.py:1824} ERROR - Task failed with exception
Traceback (most recent call last):
  File "/home/airflow/.local/lib/python3.7/site-packages/pandas/core/indexes/base.py", line 3361, in get_loc
    return self._engine.get_loc(casted_key)
  File "pandas/_libs/index.pyx", line 76, in pandas._libs.index.IndexEngine.get_loc
  File "pandas/_libs/index.pyx", line 108, in pandas._libs.index.IndexEngine.get_loc
  File "pandas/_libs/hashtable_class_helper.pxi", line 5198, in pandas._libs.hashtable.PyObjectHashTable.get_item
  File "pandas/_libs/hashtable_class_helper.pxi", line 5206, in pandas._libs.hashtable.PyObjectHashTable.get_item
KeyError: 'logdate'

The above exception was the direct cause of the following exception:

Traceback (most recent call last):
  File "/home/airflow/.local/lib/python3.7/site-packages/airflow/operators/python.py", line 181, in execute
    return_value = self.execute_callable()
  File "/home/airflow/.local/lib/python3.7/site-packages/airflow/operators/python.py", line 198, in execute_callable
    return self.python_callable(*self.op_args, **self.op_kwargs)
  File "/opt/airflow/dags/etl.py", line 157, in request_api
    df["logdate"] = pd.to_datetime(df["logdate"], unit='ms', errors='coerce')
  File "/home/airflow/.local/lib/python3.7/site-packages/pandas/core/frame.py", line 3458, in __getitem__
    indexer = self.columns.get_loc(key)
  File "/home/airflow/.local/lib/python3.7/site-packages/pandas/core/indexes/base.py", line 3363, in get_loc
    raise KeyError(key) from err
KeyError: 'logdate'
[2025-10-16T13:19:57.362+0000] {taskinstance.py:1350} INFO - Marking task as FAILED. dag_id=csv_etl_pipeline, task_id=request_api, execution_date=20251016T131800, start_date=20251016T131956, end_date=20251016T131957
[2025-10-16T13:19:57.376+0000] {standard_task_runner.py:109} ERROR - Failed to execute job 4 for task request_api ('logdate'; 83)
[2025-10-16T13:19:57.424+0000] {local_task_job_runner.py:225} INFO - Task exited with return code 1
[2025-10-16T13:19:57.449+0000] {taskinstance.py:2651} INFO - 0 downstream tasks scheduled from follow-on schedule check
